Workbook

Sheet Portada
A1: Kuajo Automation — Planeación y evaluación del proyecto de automatización para Lácteos Pomar (PM4R)
A2: Caso académico · Proyecto Integrador APM 2026-2 · Valores en COP sin IVA · Precios y tasas a octubre de 2026
A4: Indicador | B4: Valor | C4: Lectura
A5: Precio de la oferta (Fase 1, sin IVA) | B5: =Precio_Kuajo!$C$19 -> 8.5259187e+09 | C5: Lo que Pomar paga a Kuajo
A6: Precio en US$ | B6: =Precio_Kuajo!$C$19/Supuestos!$B$6 -> 2604534.8 | C6: A la TRM de octubre de 2026
A7: Duración (semanas) | B7: =Cronograma!$G$44 -> 48 | C7: Ruta crítica del cronograma
A8: VPN para Pomar a la TIO | B8: =Flujo_Pomar!$B$33 -> 1.5013918e+10 | C8: Positivo = la inversión crea valor
A9: TIR para Pomar | B9: =Flujo_Pomar!$B$35 -> 0.48963311 | C9: Comparar con la TIO
A10: TIO de Pomar | B10: =Supuestos!$B$31 -> 0.13731408 | C10: WACC + prima de proyecto
A11: Recuperación simple de Pomar (años) | B11: =Flujo_Pomar!$B$36 -> 2.2332537
A12: Recuperación descontada de Pomar (años) | B12: =Flujo_Pomar!$B$37 -> 2.7082746
A13: Factor de beneficios de equilibrio | B13: =Sensibilidad!$M$16 -> 0.39299608 | C13: Los beneficios pueden caer hasta este nivel y el VPN sigue ≥ 0
A14: Utilidad neta de Kuajo en el proyecto | B14: =Kuajo_PyG_Flujo!$B$56 -> 9.3452821e+08 | C14: Después de salarios, gastos, contingencia e impuestos
A15: Margen neto de Kuajo | B15: =Kuajo_PyG_Flujo!$B$57 -> 0.10961026
A16: VPN para Kuajo (TIO 20 %) | B16: =Kuajo_PyG_Flujo!$B$61 -> 9.4017867e+08
A17: Saldo de caja mínimo de Kuajo | B17: =Kuajo_PyG_Flujo!$B$62 -> -1.3161225e+09 | C17: Negativo = meses financiados con el crédito rotativo
A18: Cobertura de la contingencia sobre el riesgo esperado | B18: =Riesgos!$L$20 -> 1.2277561 | C18: ≥ 1 = la contingencia cubre el valor esperado de los riesgos
A19: Crédito rotativo máximo de Kuajo | B19: =Kuajo_PyG_Flujo!$B$63 -> 1.3161225e+09 | C19: Por el cobro a 30 días; cupo y tasa en Supuestos
A20: Hojas del libro
A21: Supuestos | B21: Todos los datos de entrada con su fuente
A22: VSM_Actual | B22: Estado actual de la línea de yogures: VSM, OEE, cuello de botella, lead time y KPIs base
A23: Lineas_2_3 | B23: Resultados esperados de las líneas 2 y 3 y del proyecto de planta completa (referencia ±30 %)
A24: Recursos_compartidos | B24: Capacidad y utilización de los recursos que comparten las 3 líneas
A25: Nomina_Kuajo | B25: Salarios de los 6 integrantes, factor prestacional y gastos generales
A26: Cotizaciones | B26: Precios de referencia de cada suministro, con fuente o marcados como estimación
A27: Precio_Kuajo | B27: Del costo de Kuajo al precio de la oferta
A28: Cronograma | B28: Actividades, ruta crítica (CPM) y Gantt
A29: Curva_S | B29: Valor planificado mensual y acumulado
A30: EDT | B30: Estructura desglosada del trabajo
A31: Beneficios_OPEX | B31: Margen por kg, beneficios anuales y costos de operación de Pomar
A32: Flujo_Pomar | B32: Flujo de caja, VPN, TIR y recuperación de Pomar
... A42: Simulacion | B42: Resultados del simulador de eventos discretos (sim.py, sección 6.9): escenarios actual y propuesto, 10 réplicas
A43: Convención de colores: azul = dato de entrada · negro = fórmula · verde = vínculo a otra hoja. El libro tiene 23 hojas: portada y 22 hojas de cálculo.

Sheet Supuestos
A1: Supuestos del modelo — Proyecto de automatización Kuajo Automation → Lácteos Pomar
A2: Azul = dato de entrada editable · Negro = fórmula · Verde = vínculo a otra hoja · Fondo amarillo = supuesto clave. Valores en COP sin IVA salvo que se indique.
A4: Parámetro | B4: Valor | C4: Unidad | D4: Fuente o justificación
A5: Macroeconomía y tasas
A6: TRM (tasa de cambio) | B6: 3273.49 | C6: COP/USD | D6: TRM del 3–5 oct. 2026 (Noticias Caracol, 5 oct. 2026)
A7: Inflación esperada Colombia (horizonte 2 años) | B7: 0.04 | C7: % anual | D7: Banco de la República, encuesta de expectativas de sept. 2026: 4,0 % a dos años
A8: Inflación esperada EE. UU. | B8: 0.025 | C8: % anual | D8: Supuesto (meta de la Reserva Federal + margen); se usa solo para convertir el costo de capital a COP
A9: Tasa de política monetaria Banco de la República | B9: 0.1225 | C9: % anual | D9: Banco de la República, decisión del 30 sept. 2026 (12,25 %)
A10: Tasa de impuesto de renta (personas jurídicas) | B10: 0.35 | C10: % | D10: Estatuto Tributario art. 240; Damodaran, ctryprem (Colombia 35 %, ene. 2026)
A11: Importación: componentes del costo de nacionalización (sobre el valor FOB de cada equipo importado)
A12: Flete internacional (marítimo desde Europa o EE. UU.; aéreo para instrumentos pequeños) | B12: 0.03 | C12: % del FOB | D12: ≈ 6 contenedores de 40 pies a US$3.000–4.500 cada uno sobre ≈ US$0,97 millones FOB ≈ 2,5 %; se toma 3 % por envíos aéreos. Referencia: 20 pies Port Everglades–Cartagena 1.469 € en 4 días (iContainers, oct. 2026)
A13: Seguro de transporte internacional | B13: 0.005 | C13: % del FOB | D13: Prima habitual de seguro de carga de 0,3–0,5 % del valor CIF; se toma el extremo alto por ser equipo sensible
A14: Agencia de aduanas, gastos portuarios y documentales | B14: 0.015 | C14: % del FOB | D14: Banco Mundial (Doing Business): cumplimiento fronterizo US$545 y documental US$50 por embarque en Colombia, más honorarios de la agencia (obligatoria para importaciones > US$1.000 FOB, trade.gov)
A15: Transporte terrestre Cartagena–Cajicá con seguro | B15: 0.015 | C15: % del FOB | D15: Mundo Marítimo: US$1.330 por contenedor Cartagena–Bogotá (2019), ajustado a ≈ US$1.900 en 2026 × 6 contenedores ≈ 1,2 %; se toma 1,5 % por carga sobredimensionada de la celda
A16: Arancel de importación | B16: 0 | C16: % del FOB | D16: Decreto 272 de 2018: arancel 0 % para bienes de capital no producidos en Colombia; los Decretos 2616 de 2022 y 324 de 2024 solo restablecen subpartidas con producción nacional (bombas, refrigeradores, cables). Los robots (subpartida 8479.50.00.00, a confirmar con la agencia de aduanas) se compran de fabricación sueca con certificado de origen UE (Acuerdo Comercial UE–Colombia, 0 %); E+H, Alfa Laval y Mettler-Toledo también son de origen UE y Rockwell, Cisco y Dell de EE. UU. (TLC, 0 %). Riesgo residual: 5 % ≈ $160 M, cubierto por la contingencia.
A17: Bodegaje en puerto, demoras e imprevistos logísticos | B17: 0.015 | C17: % del FOB | D17: Reserva para almacenamiento en puerto, inspección física de la DIAN y demoras (tiempo de importación en Colombia: 112 h de cumplimiento fronterizo + 64 h documental, Banco Mundial)
A18: Costo total de nacionalización de equipos importados | B18: =B12+B13+B14+B15+B16+B17 -> 0.08 | C18: % del valor FOB | D18: Suma de los componentes anteriores; se aplica a cada ítem importado de la hoja Cotizaciones
A19: Costo de capital de Pomar (WACC) y tasa de oportunidad
A20: Tasa libre de riesgo (bono del Tesoro EE. UU. a 10 años) | B20: 0.0418 | C20: % | D20: Damodaran, Historical Implied ERP, inicio de 2026: 4,18 %
A21: Beta apalancada industria de alimentos procesados | B21: 0.61 | C21: — | D21: Damodaran, Cost of Capital by industry (Food Processing), ene. 2026
A22: Prima de riesgo de mercado madura | B22: 0.0423 | C22: % | D22: Damodaran, prima implícita ene. 2026: 4,23 %
A23: Prima de riesgo país Colombia | B23: 0.0285 | C23: % | D23: Damodaran, ctryprem (Baa3), ene. 2026: 2,85 %
A24: Deuda / (Deuda + Patrimonio) | B24: 0.3043 | C24: % | D24: Damodaran, Food Processing, ene. 2026: 30,43 %
A25: Diferencial de crédito corporativo sobre la tasa BanRep | B25: 0.04 | C25: % | D25: Supuesto: crédito comercial para empresa mediana
A26: Costo del patrimonio en USD (CAPM) | B26: =B20+B21*(B22+B23) -> 0.084988 | C26: % | D26: Ke = Rf + β·(ERP + CRP)
A27: Costo del patrimonio en COP | B27: =(1+B26)*(1+B7)/(1+B8)-1 -> 0.10086587 | C27: % | D27: Ajuste por diferencial de inflación (paridad de Fisher)
A28: Costo de la deuda después de impuestos (COP) | B28: =(B9+B25)*(1-B10) -> 0.105625 | C28: % | D28: Kd = (tasa BanRep + diferencial)·(1 − t)
A29: WACC de Pomar (COP nominal) | B29: =(1-B24)*B27+B24*B28 -> 0.10231408 | C29: % | D29: Promedio ponderado
A30: Prima de riesgo del proyecto (tecnológico, primera implementación) | B30: 0.035 | C30: % | D30: Supuesto conservador por riesgo de ejecución y de adopción
A31: Tasa de oportunidad (TIO) de Pomar para descontar el proyecto | B31: =B29+B30 -> 0.13731408 | C31: % | D31: TIO = WACC + prima de proyecto
A32: Tasa de oportunidad de Kuajo Automation (empresa nueva) | B32: 0.2 | C32: % efectivo anual | D32: Supuesto: costo del patrimonio de una empresa pequeña de servicios recién creada (Ke COP + prima por tamaño y etapa temprana)
A33: Nómina y cargas laborales (Colombia 2026)
A34: Salario mínimo mensual 2026 | B34: 1750905 | C34: COP/mes | D34: Decreto 1469 de 2025 (Holland & Knight, dic. 2025)
A35: Auxilio de transporte 2026 (salarios ≤ 2 SMMLV) | B35: 249095 | C35: COP/mes | D35: Decreto 1470 de 2025
A36: Aporte a pensión (empleador) | B36: 0.12 | C36: % | D36: Ley 100 de 1993; tabla de prestaciones 2026 (calcucolombia.co)
A37: ARL riesgo II (ingenieros que trabajan en planta) | B37: 0.01044 | C37: % | D37: Decreto 1295 de 1994, tabla de cotización ARL
A38: ARL riesgo III (operarios de planta) | B38: 0.02436 | C38: % | D38: Decreto 1295 de 1994
A39: Caja de compensación familiar | B39: 0.04 | C39: % | D39: Ley 21 de 1982
A40: Prima de servicios | B40: 0.0833 | C40: % | D40: Código Sustantivo del Trabajo art. 306
A41: Cesantías | B41: 0.0833 | C41: % | D41: CST art. 249
...

Sheet Nomina_Kuajo
A1: Nómina y costos de Kuajo Automation durante el proyecto
A2: Salarios mensuales en COP 2026. Referencias de mercado: Indeed Colombia (sept. 2026).
A4: Rol | B4: Integrante | C4: Salario mensual | D4: Factor prestacional | E4: Costo mensual empresa | F4: Meses en el proyecto | G4: Costo total | H4: Referencia de mercado
A5: R1 Gerente de proyecto | B5: Duvan Felipe Pacheco Rodriguez | C5: 7500000 | D5: =Supuestos!$B$44 -> 1.38874 | E5: =C5*D5 -> 10415550 | F5: =Supuestos!$B$48 -> 12 | G5: =E5*F5 -> 124986600 | H5: Indeed: gerente de proyectos, promedio $6.653.365/mes; rango $3,7–11,9 M (11 sept. 2026). Se paga por encima del promedio por ser responsable del contrato y del P&G.
A6: R2 Arquitecta TDI (OT/IT) | B6: Paula Valentina Alvarez Chaparro | C6: 6500000 | D6: =Supuestos!$B$44 -> 1.38874 | E6: =C6*D6 -> 9026810 | F6: =Supuestos!$B$48 -> 12 | G6: =E6*F6 -> 108321720 | H6: Indeed: ingeniero de automatización, máximo $5.590.333/mes; se ubica sobre el máximo por especialidad en MES/ERP e ISA-95.
A7: R3 Ingeniero de procesos | B7: David Felipe Garcia Lopez | C7: 5000000 | D7: =Supuestos!$B$44 -> 1.38874 | E7: =C7*D7 -> 6943700 | F7: =Supuestos!$B$48 -> 12 | G7: =E7*F7 -> 83324400 | H7: Indeed: ingeniero de automatización, promedio $3.267.929 y máximo $5.590.333/mes (17 sept. 2026).
A8: R4 Ingeniero de producción | B8: Juan Angel Vargas Rodriguez | C8: 5000000 | D8: =Supuestos!$B$44 -> 1.38874 | E8: =C8*D8 -> 6943700 | F8: =Supuestos!$B$48 -> 12 | G8: =E8*F8 -> 83324400 | H8: Ídem; incluye simulación con Tecnomatix.
A9: R5 Ingeniero de control y robótica | B9: Jose Luis Pulido Fonseca | C9: 5500000 | D9: =Supuestos!$B$44 -> 1.38874 | E9: =C9*D9 -> 7638070 | F9: =Supuestos!$B$48 -> 12 | G9: =E9*F9 -> 91656840 | H9: Ídem, con prima por robótica y seguridad de máquinas.
A10: R6 Ingeniero de supervisión y comunicaciones | B10: Ian Saonni Rodriguez Pulido | C10: 5000000 | D10: =Supuestos!$B$44 -> 1.38874 | E10: =C10*D10 -> 6943700 | F10: =Supuestos!$B$48 -> 12 | G10: =E10*F10 -> 83324400 | H10: Ídem; SCADA Ignition, gemelo digital y redes.
A11: Total equipo | C11: =SUM(C5:C10) -> 34500000 | E11: =SUM(E5:E10) -> 47911530 | G11: =SUM(G5:G10) -> 574938360
A13: Costo horario del equipo (COP/h) | B13: =E11/(6*Supuestos!$B$46) -> 49907.844 | C13: Tarifa facturada / costo horario | E13: =Supuestos!$B$47/B13 -> 3.0055396
A15: Gastos generales de Kuajo
A16: Concepto | B16: Tipo | C16: Valor unitario | D16: Cantidad | E16: Total | F16: Moneda | G16: Total COP | H16: Justificación
A17: Oficina compartida (coworking, 6 puestos) | B17: Mensual | C17: 4000000 | D17: 12 | E17: =C17*D17 -> 48000000 | F17: COP | G17: =E17*IF(F17="USD",Supuestos!$B$6,1) -> 48000000 | H17: Estimación de coworking en Bogotá
A18: Contador y revisoría externa | B18: Mensual | C18: 1500000 | D18: 12 | E18: =C18*D18 -> 18000000 | F18: COP | G18: =E18*IF(F18="USD",Supuestos!$B$6,1) -> 18000000 | H18: Estimación de honorarios
A19: Transporte y viáticos a Cajicá | B19: Mensual | C19: 3000000 | D19: 12 | E19: =C19*D19 -> 36000000 | F19: COP | G19: =E19*IF(F19="USD",Supuestos!$B$6,1) -> 36000000 | H19: ≈ 3 visitas semanales; 1 vehículo compartido
A20: Telecomunicaciones, nube y GitHub | B20: Mensual | C20: 800000 | D20: 12 | E20: =C20*D20 -> 9600000 | F20: COP | G20: =E20*IF(F20="USD",Supuestos!$B$6,1) -> 9600000 | H20: Estimación
A21: Seguros, dotación, EPP y varios | B21: Mensual | C21: 1200000 | D21: 12 | E21: =C21*D21 -> 14400000 | F21: COP | G21: =E21*IF(F21="USD",Supuestos!$B$6,1) -> 14400000 | H21: Estimación
A22: Computadores portátiles de ingeniería | B22: Único | C22: 6500000 | D22: 6 | E22: =C22*D22 -> 39000000 | F22: COP | G22: =E22*IF(F22="USD",Supuestos!$B$6,1) -> 39000000 | H22: Equipo con capacidad para RobotStudio y Tecnomatix
A23: Studio 5000 Logix Designer + Logix Emulate (licencia de desarrollo) | B23: Único | C23: 12000 | D23: 1 | E23: =C23*D23 -> 12000 | F23: USD | G23: =E23*IF(F23="USD",Supuestos!$B$6,1) -> 39281880 | H23: Estimación; cotizar con distribuidor Rockwell
A24: RobotStudio Premium (suscripción anual) | B24: Único | C24: 4000 | D24: 1 | E24: =C24*D24 -> 4000 | F24: USD | G24: =E24*IF(F24="USD",Supuestos!$B$6,1) -> 13093960 | H24: Estimación; cotizar con ABB
A25: Tecnomatix Plant Simulation (suscripción anual) | B25: Único | C25: 15000 | D25: 1 | E25: =C25*D25 -> 15000 | F25: USD | G25: =E25*IF(F25="USD",Supuestos!$B$6,1) -> 49102350 | H25: Estimación; cotizar con Siemens
A26: Constitución de la S.A.S. y registro mercantil | B26: Único | C26: 2000000 | D26: 1 | E26: =C26*D26 -> 2000000 | F26: COP | G26: =E26*IF(F26="USD",Supuestos!$B$6,1) -> 2000000 | H26: Estimación
A27: Total gastos generales | G27: =SUM(G17:G26) -> 268478190
A28: de los cuales mensuales (COP/mes) | G28: =SUMIFS(C17:C26,B17:B26,"Mensual") -> 10500000
A29: de los cuales únicos (mes 0) | G29: =SUMIFS(G17:G26,B17:B26,"Único") -> 142478190

Sheet VSM_Actual
A1: Estado actual de la línea de yogures: VSM, OEE, cuello de botella, lead time y KPIs base
A2: Situación actual = supuestos del caso calibrados con el problema (OEE 55 %, cambio 90 min, rechazo 3 %); se validan en la visita industrial. Futuro = con la propuesta (informe, sección 7).
A4: Parámetro | B4: Situación actual | C4: Con la propuesta | D4: Cálculo, fuente o justificación
A5: 1. Demanda y tiempo disponible
A6: Demanda de los clientes (kg/día) | B6: =Supuestos!$B$66 -> 52400 | C6: =Supuestos!$B$66 -> 52400 | D6: Contrato con cadenas + lanzamiento del griego: la demanda ya es de 52.400 kg/día
A7: Producción de la línea (kg/día) | B7: =Supuestos!$B$62 -> 43700 | C7: =Supuestos!$B$66 -> 52400 | D7: Supuestos (suma de las 3 recetas)
A8: Cumplimiento de la demanda | B8: =B7/B6 -> 0.83396947 | C8: =C7/C6 -> 1 | D8: Producción / demanda: hoy se dejan de atender ≈ 8.700 kg/día
A9: Turnos por día | B9: 2 | C9: 2 | D9: Informe, sección 3: 2 turnos de 8 h, 6 días a la semana
A10: Pausas y relevo por turno (min) | B10: 60 | C10: 60 | D10: Almuerzo, relevo y alistamiento de turno
A11: Tiempo disponible por día (min) | B11: =B9*(480-B10) -> 840 | C11: =C9*(480-C10) -> 840 | D11: 2 × (480 − 60) = 840 min (igual que en la sección 7.4)
A12: Takt time de la línea (s por kg) | B12: =B11*60/B6 -> 0.96183206 | C12: =C11*60/C6 -> 0.96183206 | D12: Tiempo disponible / demanda: el ritmo al que habría que producir para cumplir
A13: Ritmo real de producción (s por kg) | B13: =B11*60/B7 -> 1.1533181 | C13: =C11*60/C7 -> 0.96183206 | D13: Hoy la línea va 20 % más lenta que el takt
A14: Throughput de la línea (kg/h) | B14: =B7/(B11/60) -> 3121.4286 | C14: =C7/(C11/60) -> 3742.8571 | D14: Producción / horas disponibles (14 h)
A15: Producción por turno (kg/turno) | B15: =B7/B9 -> 21850 | C15: =C7/C9 -> 26200 | D15: Producción / 2 turnos
A17: 2. Producción por receta (kg/día y unidades)
A18: Y1 fresa (vaso 150 g): kg/día | B18: =Supuestos!$B$59 -> 26400 | C18: =Supuestos!$B$63 -> 30000 | D18: Supuestos
A19: Y1 fresa (vaso 150 g): unidades/día | B19: =B18/0.15 -> 176000 | C19: =C18/0.15 -> 200000 | D19: kg/día / 0,15 kg por unidad
A20: Y1 fresa (vaso 150 g): lotes/día | B20: =B18/11364 -> 2.3231257 | C20: =C18/11364 -> 2.6399155 | D20: kg/día / 11.364 kg por lote (sección 7.4)
A21: Y1 fresa (vaso 150 g): cajas/día | B21: =B19/24 -> 7333.3333 | C21: =C19/24 -> 8333.3333 | D21: 24 unidades por caja
A22: Y1 fresa (vaso 150 g): pallets/día | B22: =B21/112 -> 65.47619 | C22: =C21/112 -> 74.404762 | D22: 112 cajas por pallet (patrón P1, sección 7.5)
A23: Y2 griego (vaso 500 g): kg/día | B23: =Supuestos!$B$60 -> 5900 | C23: =Supuestos!$B$64 -> 10000 | D23: Supuestos
A24: Y2 griego (vaso 500 g): unidades/día | B24: =B23/0.5 -> 11800 | C24: =C23/0.5 -> 20000 | D24: kg/día / 0,5 kg por unidad
A25: Y2 griego (vaso 500 g): lotes/día | B25: =B23/3054 -> 1.9318926 | C25: =C23/3054 -> 3.2743942 | D25: kg/día / 3.054 kg por lote (sección 7.4)
A26: Y2 griego (vaso 500 g): cajas/día | B26: =B24/12 -> 983.33333 | C26: =C24/12 -> 1666.6667 | D26: 12 unidades por caja
A27: Y2 griego (vaso 500 g): pallets/día | B27: =B26/77 -> 12.770563 | C27: =C26/77 -> 21.645022 | D27: 77 cajas por pallet (patrón P2: 7 × 11, sección 7.5)
A28: Y3 kéfir (botella 1 L): kg/día | B28: =Supuestos!$B$61 -> 11400 | C28: =Supuestos!$B$65 -> 12400 | D28: Supuestos
A29: Y3 kéfir (botella 1 L): unidades/día | B29: =B28/1.03 -> 11067.961 | C29: =C28/1.03 -> 12038.835 | D29: kg/día / 1,03 kg por unidad
A30: Y3 kéfir (botella 1 L): lotes/día | B30: =B28/9800 -> 1.1632653 | C30: =C28/9800 -> 1.2653061 | D30: kg/día / 9.800 kg por lote (sección 7.4)
A31: Y3 kéfir (botella 1 L): cajas/día | B31: =B29/12 -> 922.3301 | C31: =C29/12 -> 1003.2362 | D31: 12 unidades por caja
A32: Y3 kéfir (botella 1 L): pallets/día | B32: =B31/45 -> 20.496224 | C32: =C31/45 -> 22.294139 | D32: 45 cajas por pallet (patrón P3, sección 7.5)
A33: Leche requerida (kg/día) | B33: =B18*Beneficios_OPEX!$B$8+B23*Beneficios_OPEX!$C$8+B28*Beneficios_OPEX!$D$8 -> 50929.4 | C33: =C18*Beneficios_OPEX!$B$8+C23*Beneficios_OPEX!$C$8+C28*Beneficios_OPEX!$D$8 -> 68098 | D33: kg de leche por kg de producto (hoja Beneficios_OPEX, fila 8: 0,757 / 3,274 / 1,02; sección 7.1); límite 70.000 L/día ≈ 72.100 kg
A35: 3. Llenadora de vasos U-232 (Y1 y Y2): OEE y carga
A36: Velocidad nominal formato 150 g (vasos/h) | B36: 28800 | C36: 28800 | D36: Sección 7.4: 16 vasos por ciclo × 30 ciclos/min
A37: Velocidad nominal formato 500 g (vasos/h) | B37: 7200 | C37: 7200 | D37: Sección 7.4: 6 vasos por ciclo × 20 ciclos/min
A38: Tiempo de llenado a velocidad nominal de las unidades buenas (h/día) | B38: =B19/B36+B24/B37 -> 7.75 | C38: =C19/C36+C24/C37 -> 9.7222222 | D38: Unidades buenas / velocidad nominal
A39: Cambios de formato o receta por día | B39: 2 | C39: 2 | D39: Secuencia diaria Y1 → Y2 → Y1 (sección 7.10)
A40: Duración de cada cambio (min) | B40: 90 | C40: 35 | D40: Hoy: CIP y ajustes manuales (problema P2). Con la propuesta: receta ISA-88 y CIP automático (sección 7.10)
A41: Fallas de la llenadora por día | B41: 2.2 | C41: 1.5 | D41: Hoy: atascos de vasos, falla de sellado y ajustes de peso. Con la propuesta: mantenimiento preventivo y predictivo con datos del historian (sección 6.8)
A42: Tiempo medio de reparación de la llenadora, MTTR (min) | B42: 25 | C42: 20 | D42: Con la propuesta: diagnóstico por alarmas en la HMI y repuestos críticos en sitio
A43: Esperas y microparadas por día (min) | B43: 30 | C43: 15 | D43: Hoy: espera de producto por fermentaciones fuera de tiempo. Con la propuesta: secuenciación por el MES
...

Sheet Simulacion
A1: Simulación de eventos discretos de la línea 1 (sim.py): resultados que validan los KPIs del VSM y de la propuesta
A2: Paso de 1 minuto, 13 semanas por réplica (1 de calentamiento), 10 réplicas con semillas 1 a 10. Valores en azul = salida de sim.py copiada como dato; para actualizarlos se corre "python3 sim.py 10" y se pegan los valores de sim_results.json. El modelo de Tecnomatix Plant Simulation replica esta misma estructura (anexo D).
A4: Parámetros por escenario
A5: Parámetro | B5: Actual | C5: Actual con demanda objetivo | D5: Propuesta con pausas escalonadas | E5: Propuesta con pausas fijas | F5: Fuente
A6: Demanda o programa Y1 (kg/día) | B6: 26400 | C6: 30000 | D6: 30000 | E6: 30000 | F6: VSM_Actual / Supuestos
A7: Demanda o programa Y2 (kg/día) | B7: 5900 | C7: 10000 | D7: 10000 | E7: 10000 | F7: VSM_Actual / Supuestos
A8: Demanda o programa Y3 (kg/día) | B8: 11400 | C8: 12400 | D8: 12400 | E8: 12400 | F8: VSM_Actual / Supuestos
A9: Cambio de formato de la llenadora (min) | B9: 90 | C9: 90 | D9: 35 | E9: 35 | F9: VSM_Actual (actual) y SMED de la propuesta
A10: MTBF de la llenadora de vasos (h) | B10: 4.356 | C10: 4.356 | D10: 8.056 | E10: 8.056 | F10: VSM_Actual
A11: MTTR de la llenadora de vasos (min) | B11: 25 | C11: 25 | D11: 20 | E11: 20 | F11: VSM_Actual
A12: Rendimiento de velocidad de la llenadora | B12: 0.835 | C12: 0.835 | D12: 0.913 | E12: 0.913 | F12: VSM_Actual
A13: Desperdicio de envasado | B13: 0.03 | C13: 0.03 | D13: 0.01 | E13: 0.01 | F13: VSM_Actual
A14: Horas extra por semana | B14: 75 | C14: 75 | D14: 0 | E14: 0 | F14: VSM_Actual
A15: Pausas de la llenadora | B15: Fijas (almuerzo común) | C15: Fijas | D15: Escalonadas (06:00–22:00 continuo) | E15: Fijas | F15: Sección 6.9
A17: Resultados (media de 10 réplicas; ± = desviación estándar)
A18: Indicador | B18: Actual | C18: Actual con demanda objetivo | D18: Propuesta con pausas escalonadas | E18: Propuesta con pausas fijas | F18: Unidad
A19: Producción vendible total | B19: 41186.202 | C19: 38657.052 | D19: 50874.133 | E19: 48960.413 | F19: kg/día
A20: ± desviación | B20: 201.6581 | C20: 311.7304 | D20: 38.733 | E20: 210.123 | F20: kg/día
A21: Producción vendible Y1 | B21: 24704.727 | C21: 22134.375 | D21: 29077.125 | E21: 27951.189 | F21: kg/día
A22: Producción vendible Y2 | B22: 5506.2776 | C22: 7347.6085 | D22: 9564.3953 | E22: 9311.8122 | F22: kg/día
A23: Producción vendible Y3 | B23: 10975.198 | C23: 9175.0683 | D23: 12232.613 | E23: 11697.412 | F23: kg/día
A24: OEE de la llenadora de vasos | B24: 0.5177 | C24: 0.5118 | D24: 0.5867 | E24: 0.6469 | F24: %
A25: Ocupación de la llenadora de vasos | B25: 0.9519 | C25: 0.9181 | D25: 0.7624 | E25: 0.84 | F25: %
A26: Ocupación de los fermentadores | B26: 0.9811 | C26: 0.9865 | D26: 0.9826 | E26: 0.9821 | F26: %
A27: Ocupación de la llenadora de botellas | B27: 0.1714 | C27: 0.1446 | D27: 0.143 | E27: 0.156 | F27: %
A28: Tiempo de paso (MLT) de Y1 | B28: 116.6644 | C28: 116.7263 | D28: 81.0199 | E28: 82.0115 | F28: h
A29: Lotes atrasados al final | B29: 2.7 | C29: 121.3 | D29: 2 | E29: 21.4 | F29: lotes
A30: Demanda o programa total | B30: =SUM(B6:B8) -> 43700 | C30: =SUM(C6:C8) -> 52400 | D30: =SUM(D6:D8) -> 52400 | E30: =SUM(E6:E8) -> 52400 | F30: kg/día
A31: Cumplimiento de la demanda (vendible / programa) | B31: =B19/B30 -> 0.94247603 | C31: =C19/C30 -> 0.73772999 | D31: =D19/D30 -> 0.9708804 | E31: =E19/E30 -> 0.93435903 | F31: %
A32: Aumento de producción vendible frente al actual | B32: =B19/$B$19-1 -> 0 | C32: =C19/$B$19-1 -> -0.061407716 | D32: =D19/$B$19-1 -> 0.23522273 | E32: =E19/$B$19-1 -> 0.18875765 | F32: %
A34: Lectura
A35: La propuesta solo cumple la demanda objetivo (97 % vendible y atraso estable) si las pausas de la llenadora se escalonan; con pausas fijas el atraso crece semana a semana. Los fermentadores siguen ocupados cerca del 98 %, por lo que la siguiente restricción después de la llenadora es la fermentación.

Sheet Lineas_2_3
A1: Líneas 2 y 3: resultados esperados (referencia ±30 %) y proyecto de planta completa
A2: La línea 1 (yogures) está calculada en detalle en las demás hojas. Las líneas 2 (quesos) y 3 (UHT) son una referencia de ±30 % con un método simplificado: sin capital de trabajo, con todo el precio depreciado a 10 años y con recuperación = inversión / flujo promedio de los años 2 a 7. Fase 2 = línea 3 (UHT) y Fase 3 = línea 2 (quesos), según el orden recomendado.
A4: 1. Datos productivos | B4: Línea 1: yogures | C4: Línea 2: quesos | D4: Línea 3: UHT y bebidas | E4: Cálculo, fuente o justificación
A5: Leche asignada a la línea (L/día) | B5: 70000 | C5: 60000 | D5: 90000 | E5: Informe, sección 3 (cifras supuestas del caso; total del alcance 220.000 L/día)
A6: Crecimiento esperado de la producción | B6: =VSM_Actual!$C$7/VSM_Actual!$B$7-1 -> 0.19908467 | C6: 0 | D6: 0.11 | E6: L1: VSM. L2: sin crecimiento (las tinas usan 38 % y la empacadora tiene holgura; la demanda de quesos no es el detonante). L3: +11 % al subir el OEE de las llenadoras de 68 % a 80 % (capacidad +17 %, limitada por la demanda)
A7: Producción con la propuesta (kg/día) | B7: =VSM_Actual!$C$7 -> 52400 | C7: 7470 | D7: 91250 | E7: L1: VSM. L2 y L3: documento general, secciones 8.4 y 9.4
A8: Producción hoy (kg/día) | B8: =VSM_Actual!$B$7 -> 43700 | C8: =C7/(1+C6) -> 7470 | D8: =D7/(1+D6) -> 82207.207 | E8: Producción con la propuesta / (1 + crecimiento)
A9: Leche usada con la propuesta (L/día) | B9: =VSM_Actual!$C$33/1.03 -> 66114.563 | C9: 60000 | D9: 88400 | E9: L1: kg de leche / 1,03 kg/L. L2 y L3: balances de las secciones 8.4 y 9.4 del documento general
A10: Leche usada hoy (L/día) | B10: =VSM_Actual!$B$33/1.03 -> 49446.019 | C10: =C9/(1+C6) -> 60000 | D10: =D9/(1+D6) -> 79639.64 | E10: Proporcional a la producción
A11: Equipo crítico (define la capacidad) | B11: Llenadora de vasos U-232 | C11: Empacadora Q-332 | D11: Llenadoras asépticas L-431/L-432 | E11: Equipo de la línea con mayor ocupación hoy
A12: OEE del equipo crítico hoy | B12: =VSM_Actual!$B$49 -> 0.55443006 | C12: 0.58 | D12: 0.68 | E12: L1: VSM. L2: empaque y moldeo manuales (supuesto del caso). L3: las llenadoras asépticas ya traen control propio, por eso parten más alto (supuesto del caso)
A13: OEE meta | B13: =VSM_Actual!$C$49 -> 0.78012589 | C13: 0.75 | D13: 0.8 | E13: Metas de las secciones 7.9, 8.9 y 9.9 del documento general
A14: Cuello de botella hoy | B14: Llenadora de vasos (100 %) | C14: Moldeo y empaque manuales | D14: Llenadoras asépticas (OEE 68 %) | E14: Análisis de capacidad de cada línea
A15: Restricción con la propuesta | B15: Fermentadores (89 %) | C15: Tinas y prensado | D15: Tren UHT (≈ 9,3 h/día de producción) | E15: Secciones 7.3, 8.3 y 9.3 del documento general
A16: Operarios de fin de línea liberados | B16: =Supuestos!$B$74 -> 6 | C16: 4 | D16: 4 | E16: L1: 6 (Supuestos). L2: robot de moldes y paletizado, 2 por turno. L3: paletizado robotizado, 2 por turno
A17: Robótica propuesta | B17: 2 robots delta + paletizador | C17: Robot sanitario de moldes + paletizador | D17: Paletizador con 2 estaciones | E17: Sección 4 (alcance de la robotización)
A19: 2. Margen de contribución de la línea 3 por receta (COP/L) | B19: U1 leche entera 1 L | C19: U2 deslactosada 1 L | D19: U3 achocolatada 200 mL | E19: Cálculo, fuente o justificación
A20: Precio al consumidor (COP/L) | B20: 5700 | C20: 6500 | D20: 11500 | E20: Caja de 1 L entre $4.671 y $6.400 en 2022 (El Tiempo), ajustada por inflación; U3: $2.300 por 200 mL (Alpin de Alpina $4.050 en Farmatodo, marca premium). Estimaciones
A21: Margen del canal | B21: 0.25 | C21: 0.25 | D21: 0.3 | E21: Leche UHT es un producto de alta rotación y menor margen de canal que el yogur (40 %)
A22: Precio ex-fábrica (COP/L) | B22: =B20*(1-B21) -> 4275 | C22: =C20*(1-C21) -> 4875 | D22: =D20*(1-D21) -> 8050 | E22: Precio al consumidor × (1 − margen del canal)
A23: Leche por L de producto | B23: 1 | C23: 1 | D23: 0.92 | E23: U3 lleva 8 % de azúcar, cacao y estabilizante (sección 9.1)
A24: Costo de leche (COP/L) | B24: =B23*Supuestos!$B$69*(1+Supuestos!$B$70) -> 2240.7 | C24: =C23*Supuestos!$B$69*(1+Supuestos!$B$70) -> 2240.7 | D24: =D23*Supuestos!$B$69*(1+Supuestos!$B$70) -> 2061.444 | E24: Leche × precio al productor × (1 + acopio)
A25: Otros ingredientes (COP/L) | B25: 0 | C25: 150 | D25: 600 | E25: U2: lactasa; U3: cacao, azúcar y carragenina. Estimaciones
A26: Envase aséptico (COP/L) | B26: 450 | C26: 450 | D26: 900 | E26: Caja aséptica de 1 L ≈ $450; de 200 mL con pitillo ≈ $180 por unidad. Estimaciones
A27: Energía, vapor, agua y CIP (COP/L) | B27: 220 | C27: 240 | D27: 250 | E27: UHT a 140 °C con regeneración. Estimación
A28: Logística y gasto comercial (% del precio ex-fábrica) | B28: 0.1 | C28: 0.1 | D28: 0.1 | E28: Producto a temperatura ambiente: menor costo logístico que el yogur (12 %)
A29: Costo variable (COP/L) | B29: =B24+B25+B26+B27+B28*B22 -> 3338.2 | C29: =C24+C25+C26+C27+C28*C22 -> 3568.2 | D29: =D24+D25+D26+D27+D28*D22 -> 4616.444 | E29: Suma de costos variables
A30: Margen de contribución (COP/L) | B30: =B22-B29 -> 936.8 | C30: =C22-C29 -> 1306.8 | D30: =D22-D29 -> 3433.556 | E30: Precio ex-fábrica − costo variable
A31: Margen de contribución (%) | B31: =B30/B22 -> 0.2191345 | C31: =C30/C22 -> 0.26806154 | D31: =D30/D22 -> 0.4265287 | E31: La leche blanca deja poco margen; la achocolatada, mucho más
A32: Producción con la propuesta (L/día) | B32: 49500 | C32: 24750 | D32: 14140 | E32: Sección 9.4 del documento general (U3: 70.700 envases × 0,2 L)
A33: Volumen adicional (L/día) | B33: =B32-B32/(1+$D$6) -> 4905.4054 | C33: =C32-C32/(1+$D$6) -> 2452.7027 | D33: =D32-D32/(1+$D$6) -> 1401.2613 | E33: Mismo crecimiento en las 3 recetas
A34: Margen del volumen adicional de la línea 3 (COP/día) | D34: =SUMPRODUCT(B30:D30,B33:D33) -> 12611885
A35: Costo variable ponderado de la línea 3 (COP/L) | D35: =SUMPRODUCT(B29:D29,B32:D32)/SUM(B32:D32) -> 3607.0864
A37: 3. Parámetros de los beneficios | B37: Línea 1: yogures | C37: Línea 2: quesos | D37: Línea 3: UHT y bebidas | E37: Cálculo, fuente o justificación
A38: Mejora del rendimiento quesero | B38: — | C38: 0.015 | D38: — | E38: Estandarización de grasa y proteína, y control del corte y del desuerado por receta: ≈ 1–2 % más queso con la misma leche (supuesto conservador)
A39: Costo variable por kg (COP) | B39: — | C39: =60000/7470*Supuestos!$B$69*(1+Supuestos!$B$70)+1000 -> 18997.59 | D39: =D35/1.03 -> 3502.0256 | E39: L2: 8,0 L de leche por kg de queso + $1.000 de empaque, sal y cuajo. L3: costo variable ponderado / 1,03 kg/L
A40: Rechazo hoy | B40: =Supuestos!$B$71 -> 0.03 | C40: 0.03 | D40: 0.02 | E40: L2: peso y sellado al vacío. L3: sellado y peso de cajas asépticas (supuestos del caso)
A41: Rechazo con la propuesta | B41: =Supuestos!$B$72 -> 0.01 | C41: 0.01 | D41: 0.008 | E41: Metas de las secciones 8.9 y 9.9
A42: Energía, vapor y agua (COP/kg) | B42: =Supuestos!$B$76 -> 250 | C42: 350 | D42: 220 | E42: L2: cocción e hilado de Q2 y CIP. L3: tren UHT. Estimaciones
A43: Costo evitado por retiro acotado (COP) | B43: =Supuestos!$B$79 -> 800000000 | C43: 300000000 | D43: 500000000 | E43: Proporcional al valor de un día de producción de cada línea
...

Sheet Recursos_compartidos
A1: Recursos compartidos de la planta: capacidad, demanda y utilización en 3 escenarios
A2: Hoy · con la línea 1 automatizada (Fase 1) · con la planta completa (Fases 1 a 3). Capacidades y factores de consumo: supuestos del caso por validar en la visita industrial.
A4: Dato de entrada | B4: Hoy | C4: Fase 1 (línea 1) | D4: Planta completa | E4: Fuente o justificación
A5: Leche de la línea 1 (L/día) | B5: =Lineas_2_3!$B$10 -> 49446.019 | C5: =Lineas_2_3!$B$9 -> 66114.563 | D5: =Lineas_2_3!$B$9 -> 66114.563 | E5: Hoja Lineas_2_3
A6: Leche de la línea 2 (L/día) | B6: =Lineas_2_3!$C$10 -> 60000 | C6: =Lineas_2_3!$C$10 -> 60000 | D6: =Lineas_2_3!$C$9 -> 60000 | E6: Hoja Lineas_2_3
A7: Leche de la línea 3 (L/día) | B7: =Lineas_2_3!$D$10 -> 79639.64 | C7: =Lineas_2_3!$D$10 -> 79639.64 | D7: =Lineas_2_3!$D$9 -> 88400 | E7: Hoja Lineas_2_3
A8: Leche de otros productos (L/día) | B8: 40000 | C8: 40000 | D8: 40000 | E8: Leche en bolsa, mantequilla y leche condensada (sección 3)
A9: Leche total (L/día) | B9: =SUM(B5:B8) -> 229085.66 | C9: =SUM(C5:C8) -> 245754.2 | D9: =SUM(D5:D8) -> 254514.56 | E9: Suma
A10: Lotes de Y2 por día | B10: =VSM_Actual!$B$25 -> 1.9318926 | C10: =VSM_Actual!$C$25 -> 3.2743942 | D10: =VSM_Actual!$C$25 -> 3.2743942 | E10: Hoja VSM_Actual
A11: Pallets de yogur por día | B11: =VSM_Actual!$B$69 -> 98.742978 | C11: =VSM_Actual!$C$69 -> 118.34392 | D11: =VSM_Actual!$C$69 -> 118.34392 | E11: Hoja VSM_Actual
A12: Días de yogur en cámara (liberación + stock) | B12: 3 | C12: 2 | D12: 2 | E12: Yogur Y1 y Y2: 24 h de liberación + 48 h de stock hoy; 24 h de stock con el plan diario. El kéfir (Y3) se libera a las 48 h: 1 día más
A13: Pallets de queso por día | B13: 18 | C13: 18 | D13: 18 | E13: ≈ 7.470 kg/día en cajas de 10–12 kg (sección 8.5 del documento general)
A14: Pallets de UHT por día | B14: =102/(1+Lineas_2_3!$D$6) -> 91.891892 | C14: =102/(1+Lineas_2_3!$D$6) -> 91.891892 | D14: 102 | E14: ≈ 102 pallets/día con la propuesta (sección 9.4 del documento general)
A15: Días de UHT en cuarentena | B15: 7 | C15: 7 | D15: 5 | E15: Liberación electrónica en el MES en la Fase 3
A17: Factor de consumo | B17: Yogur | C17: Quesos | D17: UHT | E17: Fuente o justificación
A18: Vapor por 1.000 L procesados (kg) | B18: 120 | C18: 150 | D18: 110 | E18: Calentar de 4 a 90 °C con 90 % de regeneración ≈ 15 kg de vapor por 1.000 L, más camisas, agua caliente y CIP. Otros: 60 kg. Estimación
A19: Frío por 1.000 L/día procesados (kW) | B19: 3.5 | C19: 2 | D19: 1 | E19: El yogur enfría de 43 a 20 °C y madura el kéfir a 9 °C; el UHT sale frío de la regeneración. Otros: 1,5 kW. Estimación
A21: Recurso compartido | B21: Hoy | C21: Fase 1 (línea 1) | D21: Planta completa | E21: Capacidad y cálculo
A22: Acopio de leche | E22: Capacidad: 260000 L/día. 95 millones de litros en 2023 (Portafolio)
A23: Demanda | B23: =B9 -> 229085.66 | C23: =C9 -> 245754.2 | D23: =D9 -> 254514.56
A24: Capacidad | B24: 260000 | C24: 260000 | D24: 260000
A25: Utilización | B25: =B23/B24 -> 0.88109869 | C25: =C23/C24 -> 0.94520847 | D25: =D23/D24 -> 0.97890217
A26: Recepción de leche (R-111, 2 plataformas) | E26: Capacidad: 1000000 L/día. 2 plataformas × 25.000 L/h × 20 h; los carrotanques llegan concentrados en la madrugada
A27: Demanda | B27: =B9 -> 229085.66 | C27: =C9 -> 245754.2 | D27: =D9 -> 254514.56
A28: Capacidad | B28: 1000000 | C28: 1000000 | D28: 1000000
A29: Utilización | B29: =B27/B28 -> 0.22908566 | C29: =C27/C28 -> 0.2457542 | D29: =D27/D28 -> 0.25451456
A30: Silos de leche cruda (R-121 a R-123) | E30: Capacidad: 240000 L. 3 × 80.000 L; demanda = leche de 12 h (residencia promedio)
A31: Demanda | B31: =B9*12/24 -> 114542.83 | C31: =C9*12/24 -> 122877.1 | D31: =D9*12/24 -> 127257.28
A32: Capacidad | B32: 240000 | C32: 240000 | D32: 240000
A33: Utilización | B33: =B31/B32 -> 0.47726179 | C33: =C31/C32 -> 0.51198792 | D33: =D31/D32 -> 0.53023867
A34: Tratamiento inicial (R-131: clarificación, descremado, estandarización) | E34: Capacidad: 400000 L/día. 20.000 L/h × 20 h
A35: Demanda | B35: =B9 -> 229085.66 | C35: =C9 -> 245754.2 | D35: =D9 -> 254514.56
A36: Capacidad | B36: 400000 | C36: 400000 | D36: 400000
A37: Utilización | B37: =B35/B36 -> 0.57271415 | C37: =C35/C36 -> 0.61438551 | D37: =D35/D36 -> 0.63628641
A38: CIP-100 de recepción y silos | E38: Capacidad: 20 h/día. Lavado de cada carrotanque de 25.000 L (45 min) + 1 silo por día (1,5 h)
A39: Demanda | B39: =B9/25000*0.75+1.5 -> 8.3725698 | C39: =C9/25000*0.75+1.5 -> 8.8726261 | D39: =D9/25000*0.75+1.5 -> 9.1354369
A40: Capacidad | B40: 20 | C40: 20 | D40: 20
A41: Utilización | B41: =B39/B40 -> 0.41862849 | C41: =C39/C40 -> 0.4436313 | D41: =D39/D40 -> 0.45677184
A42: Vapor (caldera S-511), demanda pico | E42: Capacidad: 4000 kg/h. Σ leche × vapor por 1.000 L / 16 h × 1,5 (factor de pico por arranques simultáneos)
A43: Demanda | B43: =(B5*$B$18+B6*$C$18+B7*$D$18+B8*60)/1000/16*1.5 -> 2446.3015 | C43: =(C5*$B$18+C6*$C$18+C7*$D$18+C8*60)/1000/16*1.5 -> 2633.8226 | D43: =(D5*$B$18+D6*$C$18+D7*$D$18+D8*60)/1000/16*1.5 -> 2724.1638
...

Sheet Cotizaciones
A1: Cotizaciones y precios de referencia de suministros (Fase 1: línea de yogures + plataforma de planta)
A2: “Publicado” = precio de lista consultado en línea (fuente en la columna L). “Estimación” = valor de referencia de integrador, a reemplazar por 3 cotizaciones formales antes de la orden de compra.
A4: # | B4: Paquete | C4: Actividad EDT | D4: Descripción | E4: Tag o uso | F4: Cant. | G4: Moneda | H4: Precio unitario | I4: Importado | J4: Total COP | K4: Tipo de precio | L4: Fuente | M4: Grupo de compra | N4: Clase para depreciación
A5: 1 | B5: Instrumentación | C5: 4.2 | D5: Caudalímetro Coriolis higiénico (ref. E+H Promass S 300) | E5: FT-211, FT-231 | F5: 2 | G5: USD | H5: 12405.67 | I5: Sí | J5: =F5*H5*IF(G5="USD",Supuestos!$B$6,1)*IF(I5="Sí",1+Supuestos!$B$18,1) -> 87717247 | K5: Rango publicado | L5: Instrumart, Endress+Hauser Coriolis: precio «desde» de la configuración base (se clasifica como rango) | M5: Instrumentación E+H | N5: Equipo
A6: 2 | B6: Instrumentación | C6: 4.2 | D6: Caudalímetro electromagnético higiénico (ref. E+H Promag H 300) | E6: FT-212, FT-228, FT-201 | F6: 3 | G6: USD | H6: 4869.52 | I6: Sí | J6: =F6*H6*IF(G6="USD",Supuestos!$B$6,1)*IF(I6="Sí",1+Supuestos!$B$18,1) -> 51646653 | K6: Publicado | L6: Instrumart, Endress+Hauser flow meters | M6: Instrumentación E+H | N6: Equipo
A7: 3 | B7: Instrumentación | C7: 4.2 | D7: Termómetro higiénico digital (ref. E+H iTHERM TM411, incluye recargo de 8,4 %) | E7: TT-211 a TT-227, TT-201 | F7: 13 | G7: USD | H7: 522.52 | I7: Sí | J7: =F7*H7*IF(G7="USD",Supuestos!$B$6,1)*IF(I7="Sí",1+Supuestos!$B$18,1) -> 24014914 | K7: Publicado | L7: Instrumart, iTHERM TM411 ($482,03 + 8,4 % de recargo) | M7: Instrumentación E+H | N7: Equipo
A8: 4 | B8: Instrumentación | C8: 4.2 | D8: Sensor de pH digital (ref. E+H Memosens CPS77E) | E8: AT-221 a AT-224, AT-227 | F8: 5 | G8: USD | H8: 1045.59 | I8: Sí | J8: =F8*H8*IF(G8="USD",Supuestos!$B$6,1)*IF(I8="Sí",1+Supuestos!$B$18,1) -> 18482733 | K8: Publicado | L8: Instrumart, sensores de pH E+H | M8: Instrumentación E+H | N8: Equipo
A9: 5 | B9: Instrumentación | C9: 4.2 | D9: Transmisor de pH (ref. E+H Liquiline M CM42, pH/ORP) | E9: AT-221 a AT-224, AT-227 | F9: 5 | G9: USD | H9: 3645.04 | I9: Sí | J9: =F9*H9*IF(G9="USD",Supuestos!$B$6,1)*IF(I9="Sí",1+Supuestos!$B$18,1) -> 64432811 | K9: Publicado | L9: Instrumart, Liquiline M CM42 (variante pH) | M9: Instrumentación E+H | N9: Equipo
A10: 6 | B10: Instrumentación | C10: 4.2 | D10: Transmisor de conductividad del CIP (ref. E+H CM42) | E10: AT-201 | F10: 1 | G10: USD | H10: 2658.12 | I10: Sí | J10: =F10*H10*IF(G10="USD",Supuestos!$B$6,1)*IF(I10="Sí",1+Supuestos!$B$18,1) -> 9397435.6 | K10: Publicado | L10: Instrumart, Liquiline M CM42 | M10: Instrumentación E+H | N10: Equipo
A11: 7 | B11: Instrumentación | C11: 4.2 | D11: Sensor toroidal de conductividad higiénico | E11: AT-201 | F11: 1 | G11: USD | H11: 1200 | I11: Sí | J11: =F11*H11*IF(G11="USD",Supuestos!$B$6,1)*IF(I11="Sí",1+Supuestos!$B$18,1) -> 4242443 | K11: Estimación | L11: Estimación de integrador | M11: Instrumentación E+H | N11: Equipo
A12: 8 | B12: Instrumentación | C12: 4.2 | D12: Radar de nivel higiénico (ref. E+H Micropilot FMR43) | E12: LT-211, LT-226, LT-227 | F12: 3 | G12: USD | H12: 1936.25 | I12: Sí | J12: =F12*H12*IF(G12="USD",Supuestos!$B$6,1)*IF(I12="Sí",1+Supuestos!$B$18,1) -> 20536076 | K12: Publicado | L12: Instrumart, Micropilot FMR43 | M12: Instrumentación E+H | N12: Equipo
A13: 9 | B13: Instrumentación | C13: 4.2 | D13: Juego de celdas de carga higiénicas con indicador EtherNet/IP | E13: WT-211, WT-212, WT-221 a WT-224 | F13: 6 | G13: USD | H13: 6000 | I13: Sí | J13: =F13*H13*IF(G13="USD",Supuestos!$B$6,1)*IF(I13="Sí",1+Supuestos!$B$18,1) -> 1.2727329e+08 | K13: Estimación | L13: Estimación de integrador | M13: Instrumentación E+H | N13: Equipo
A14: 10 | B14: Instrumentación | C14: 4.2 | D14: Transmisores de presión y presión diferencial higiénicos | E14: PT-212, PDT-212 | F14: 2 | G14: USD | H14: 1800 | I14: Sí | J14: =F14*H14*IF(G14="USD",Supuestos!$B$6,1)*IF(I14="Sí",1+Supuestos!$B$18,1) -> 12727329 | K14: Estimación | L14: Estimación de integrador | M14: Instrumentación E+H | N14: Equipo
A15: 11 | B15: Instrumentación | C15: 4.2 | D15: Analizador NIR de proteína en línea | E15: AT-228 | F15: 1 | G15: USD | H15: 45000 | I15: Sí | J15: =F15*H15*IF(G15="USD",Supuestos!$B$6,1)*IF(I15="Sí",1+Supuestos!$B$18,1) -> 159091614 | K15: Estimación | L15: Estimación de integrador (rango de mercado US$40.000–80.000) | M15: Analizador NIR | N15: Equipo
A16: 12 | B16: Instrumentación | C16: 4.2 | D16: Interruptores de nivel vibratorios | E16: LSL-221 a LSL-224 | F16: 4 | G16: USD | H16: 600 | I16: Sí | J16: =F16*H16*IF(G16="USD",Supuestos!$B$6,1)*IF(I16="Sí",1+Supuestos!$B$18,1) -> 8484886.1 | K16: Estimación | L16: Estimación de integrador | M16: Instrumentación E+H | N16: Equipo
... A70: 66 | B70: Robótica | C70: 4.3 | D70: Integración de la celda robotizada por el integrador local: ingeniería mecánica de detalle, ensamble, cableado, programación base de los robots, FAT en taller e instalación en sitio | E70: Celda 240 | F70: 1 | G70: COP | H70: 300000000 | I70: No | J70: =F70*H70*IF(G70="USD",Supuestos!$B$6,1)*IF(I70="Sí",1+Supuestos!$B$18,1) -> 300000000 | K70: Estimación | L70: ≈ 28 % del hardware de la celda (rango habitual de integración 25–50 %); se cotiza dentro del contrato llave en mano de robots | M70: Robots y celda | N70: Equipo
D71: Total suministros (costo para Kuajo) | J71: =SUM(J5:J70) -> 5.7713914e+09
D72: Participación de precios publicados | J72: =SUMIFS(J5:J70,K5:K70,"Publicado")/J71 -> 0.12050121
D73: Participación de rangos publicados | J73: =SUMIFS(J5:J70,K5:K70,"Rango publicado")/J71 -> 0.14690073
D74: Participación de estimaciones | J74: =SUMIFS(J5:J70,K5:K70,"Estimación")/J71 -> 0.73259806
D75: Participación de los suministros cotizados en US$ (exposición cambiaria) | J75: =SUMIFS(J5:J70,G5:G70,"USD")/J71 -> 0.72883489

Sheet Instrumentos
A1: Lista única de instrumentos, funciones de control y actuadores de la línea 1 (fuente de las tablas 12.1 y 12.2, del P&ID 12.1 y de la figura 10.1)
A2: Tags según ISA-5.1: primera letra = variable; siguientes = función. Número = unidad (U-2xx). Los variadores toman el número del motor o la bomba que mueven. X = sin clasificar (lectores de código).
A4: Tag | B4: Tipo | C4: Descripción | D4: Unidad | E4: Variable y rango | F4: Señal | G4: Nuevo o existente | H4: Partida de Cotizaciones (#)
A5: FT-211 | B5: Sensor | C5: Caudalímetro másico Coriolis | D5: U-211 | E5: Caudal de leche, 0–30.000 kg/h | F5: 4–20 mA HART | G5: Nuevo | H5: 1
A6: WT-211 | B6: Sensor | C6: Celdas de carga del tanque de preparación | D6: U-211 | E6: Peso, 0–12.000 kg | F6: EtherNet/IP | G6: Nuevo | H6: 9
A7: WT-212 | B7: Sensor | C7: Celdas de carga de la tolva de polvos | D7: U-211 | E7: Peso, 0–2.000 kg | F7: EtherNet/IP | G7: Nuevo | H7: 9
A8: LT-211 | B8: Sensor | C8: Nivel por radar | D8: U-211 | E8: Nivel, 0–100 % | F8: 4–20 mA | G8: Nuevo | H8: 8
A9: TT-211 | B9: Sensor | C9: Termorresistencia PT100 | D9: U-211 | E9: Temperatura, 0–100 °C | F9: 4–20 mA | G9: Nuevo | H9: 3
A10: XI-211 | B10: Sensor | C10: Lector de código de barras de lotes de polvos, azúcar y kits | D10: U-211 | E10: Código de lote | F10: EtherNet/IP | G10: Nuevo | H10: 62
A11: FT-212 | B11: Sensor | C11: Caudalímetro electromagnético del tren térmico | D11: U-212 | E11: Caudal, 0–12.000 L/h | F11: 4–20 mA HART | G11: Nuevo | H11: 2
A12: TT-212A | B12: Sensor | C12: PT100 de calentamiento | D12: U-212 | E12: Temperatura, 0–150 °C | F12: 4–20 mA | G12: Existente (PLC OEM) → PLC de línea | H12: —
A13: TT-212B | B13: Sensor | C13: PT100 doble a la salida del tubo de retención (PCC 1) | D13: U-212 | E13: Temperatura, 0–150 °C | F13: 4–20 mA | G13: Nuevo | H13: 3
A14: TR-212B | B14: Sensor | C14: Registrador sin papel del PCC 1 | D14: U-212 | E14: Registro continuo de temperatura | F14: 4–20 mA / EtherNet/IP | G14: Nuevo | H14: 61
A15: TSL-212B | B15: Sensor | C15: Relé de temperatura baja del registrador, cableado directo a FDV-212 | D15: U-212 | E15: Límite de pasteurización | F15: Digital cableado | G15: Nuevo | H15: 61
A16: TT-212C | B16: Sensor | C16: PT100 de salida hacia el fermentador | D16: U-212 | E16: Temperatura, 0–100 °C | F16: 4–20 mA | G16: Nuevo | H16: 3
A17: PT-212 | B17: Sensor | C17: Presión de homogeneización | D17: U-212 | E17: Presión, 0–300 bar | F17: 4–20 mA | G17: Nuevo (reemplaza el manómetro local) | H17: 10
A18: PDT-212 | B18: Sensor | C18: Presión diferencial del regenerador | D18: U-212 | E18: ±2 bar | F18: 4–20 mA | G18: Nuevo | H18: 10
A19: TT-221 | B19: Sensor | C19: PT100 de incubación | D19: U-221 | E19: Temperatura, 0–100 °C | F19: 4–20 mA | G19: Nuevo | H19: 3
A20: AT-221 | B20: Sensor | C20: Sensor de pH higiénico en línea | D20: U-221 | E20: pH, 2–12 | F20: 4–20 mA HART | G20: Nuevo | H20: 4 y 5
A21: WT-221 | B21: Sensor | C21: Celdas de carga del fermentador | D21: U-221 | E21: Peso, 0–12.000 kg | F21: EtherNet/IP | G21: Nuevo | H21: 9
A22: LSL-221 | B22: Sensor | C22: Interruptor de nivel bajo vibratorio | D22: U-221 | E22: Nivel mínimo | F22: Digital (IO-Link) | G22: Nuevo | H22: 12
A23: XI-221 | B23: Sensor | C23: Lector de código del lote de cultivo (puerto aséptico) | D23: U-221 | E23: Código de lote | F23: EtherNet/IP | G23: Nuevo | H23: 62
A24: TT-222 | B24: Sensor | C24: PT100 de incubación | D24: U-222 | E24: Temperatura, 0–100 °C | F24: 4–20 mA | G24: Nuevo | H24: 3
A25: AT-222 | B25: Sensor | C25: Sensor de pH higiénico en línea | D25: U-222 | E25: pH, 2–12 | F25: 4–20 mA HART | G25: Nuevo | H25: 4 y 5
A26: WT-222 | B26: Sensor | C26: Celdas de carga del fermentador | D26: U-222 | E26: Peso, 0–12.000 kg | F26: EtherNet/IP | G26: Nuevo | H26: 9
A27: LSL-222 | B27: Sensor | C27: Interruptor de nivel bajo vibratorio | D27: U-222 | E27: Nivel mínimo | F27: Digital (IO-Link) | G27: Nuevo | H27: 12
A28: XI-222 | B28: Sensor | C28: Lector de código del lote de cultivo (puerto aséptico) | D28: U-222 | E28: Código de lote | F28: EtherNet/IP | G28: Nuevo | H28: 62
A29: TT-223 | B29: Sensor | C29: PT100 de incubación | D29: U-223 | E29: Temperatura, 0–100 °C | F29: 4–20 mA | G29: Nuevo | H29: 3
A30: AT-223 | B30: Sensor | C30: Sensor de pH higiénico en línea | D30: U-223 | E30: pH, 2–12 | F30: 4–20 mA HART | G30: Nuevo | H30: 4 y 5
A31: WT-223 | B31: Sensor | C31: Celdas de carga del fermentador | D31: U-223 | E31: Peso, 0–12.000 kg | F31: EtherNet/IP | G31: Nuevo | H31: 9
A32: LSL-223 | B32: Sensor | C32: Interruptor de nivel bajo vibratorio | D32: U-223 | E32: Nivel mínimo | F32: Digital (IO-Link) | G32: Nuevo | H32: 12
A33: XI-223 | B33: Sensor | C33: Lector de código del lote de cultivo (puerto aséptico) | D33: U-223 | E33: Código de lote | F33: EtherNet/IP | G33: Nuevo | H33: 62
A34: TT-224 | B34: Sensor | C34: PT100 de incubación | D34: U-224 | E34: Temperatura, 0–100 °C | F34: 4–20 mA | G34: Nuevo | H34: 3
A35: AT-224 | B35: Sensor | C35: Sensor de pH higiénico en línea | D35: U-224 | E35: pH, 2–12 | F35: 4–20 mA HART | G35: Nuevo | H35: 4 y 5
A36: WT-224 | B36: Sensor | C36: Celdas de carga del fermentador | D36: U-224 | E36: Peso, 0–12.000 kg | F36: EtherNet/IP | G36: Nuevo | H36: 9
A37: LSL-224 | B37: Sensor | C37: Interruptor de nivel bajo vibratorio | D37: U-224 | E37: Nivel mínimo | F37: Digital (IO-Link) | G37: Nuevo | H37: 12
A38: XI-224 | B38: Sensor | C38: Lector de código del lote de cultivo (puerto aséptico) | D38: U-224 | E38: Código de lote | F38: EtherNet/IP | G38: Nuevo | H38: 62
A39: AT-228 | B39: Sensor | C39: Analizador NIR de proteína (AE/AT) | D39: U-228 | E39: Proteína, 0–15 % | F39: 4–20 mA | G39: Nuevo | H39: 11
A40: FT-228 | B40: Sensor | C40: Caudalímetro de suero ácido | D40: U-228 | E40: Caudal, 0–8.000 L/h | F40: 4–20 mA | G40: Nuevo | H40: 2
A41: TT-225 | B41: Sensor | C41: PT100 de salida del enfriador | D41: U-225 | E41: Temperatura, 0–50 °C | F41: 4–20 mA | G41: Nuevo | H41: 3
...

Sheet Cronograma
A1: Cronograma del proyecto con ruta crítica (método CPM) y diagrama de Gantt
A2: Duraciones en semanas. ES/EF = inicio/fin más temprano; LS/LF = inicio/fin más tardío. La ruta crítica tiene holgura 0.
A3: Fecha de inicio (firma del contrato) | C3: 46398
R4: Semanas del proyecto →
A5: Código | B5: Actividad | C5: Responsable | D5: Duración (sem) | E5: Predecesoras | F5: ES | G5: EF | H5: LS | I5: LF | J5: Holgura | K5: Crítica | L5: Horas Kuajo | M5: Suministros (COP, costo) | N5: Valor planificado (COP, precio) | O5: Inicio | P5: Fin | Q5: Desfase por nivelación (sem) | R5: 1 | S5: 2 | T5: 3 | U5: 4 | V5: 5 | W5: 6 | X5: 7 | Y5: 8 | Z5: 9 | AA5: 10 | AB5: 11 | AC5: 12 | AD5: 13 | AE5: 14 | AF5: 15 | AG5: 16 | AH5: 17 | AI5: 18 | AJ5: 19 | AK5: 20 | AL5: 21 | AM5: 22 | AN5: 23 | AO5: 24 | AP5: 25 | AQ5: 26 | AR5: 27 | AS5: 28 | AT5: 29 | AU5: 30 | AV5: 31 | AW5: 32 | AX5: 33 | AY5: 34 | AZ5: 35 | BA5: 36 | BB5: 37 | BC5: 38 | BD5: 39 | BE5: 40 | BF5: 41 | BG5: 42 | BH5: 43 | BI5: 44 | BJ5: 45 | BK5: 46 | BL5: 47 | BM5: 48 | BN5: 49 | BO5: 50 | BQ5: Horas R1 | BR5: Horas R2 | BS5: Horas R3 | BT5: Horas R4 | BU5: Horas R5 | BV5: Horas R6 | BW5: Control (debe ser 0) | BX5: h/sem R1 | BY5: h/sem R2 | BZ5: h/sem R3 | CA5: h/sem R4 | CB5: h/sem R5 | CC5: h/sem R6
A6: 1.1 | B6: Acta de constitución y reunión de arranque | C6: R1 Duvan | D6: 1 | E6: — | F6: =0+Q6 -> 0 | G6: =F6+D6 -> 1 | H6: =I6-D6 -> 0 | I6: =MIN(H7,H9) -> 1 | J6: =H6-F6 -> 0 | K6: =IF(J6=0,"Sí","") -> Sí | L6: =SUM(BQ6:BV6) -> 80 | M6: =SUMIFS(Cotizaciones!$J$5:$J$70,Cotizaciones!$C$5:$C$70,A6) -> 0 | N6: =(L6*Supuestos!$B$47+M6*(1+Supuestos!$B$50))*(1+Supuestos!$B$51)/(1-Supuestos!$B$52) -> 12995951 | O6: =$C$3+F6*7 -> 46398 | P6: =$C$3+G6*7-IF(D6>0,1,0) -> 46404 | Q6: 0 | R6: =IF(AND(R$5>$F6,R$5<=$G6),IF($K6="Sí",2,1),IF(AND($D6=0,R$5=$G6),3,"")) -> 2 | S6: =IF(AND(S$5>$F6,S$5<=$G6),IF($K6="Sí",2,1),IF(AND($D6=0,S$5=$G6),3,"")) | T6: =IF(AND(T$5>$F6,T$5<=$G6),IF($K6="Sí",2,1),IF(AND($D6=0,T$5=$G6),3,"")) | U6: =IF(AND(U$5>$F6,U$5<=$G6),IF($K6="Sí",2,1),IF(AND($D6=0,U$5=$G6),3,"")) | V6: =IF(AND(V$5>$F6,V$5<=$G6),IF($K6="Sí",2,1),IF(AND($D6=0,V$5=$G6),3,"")) | W6: =IF(AND(W$5>$F6,W$5<=$G6),IF($K6="Sí",2,1),IF(AND($D6=0,W$5=$G6),3,"")) | X6: =IF(AND(X$5>$F6,X$5<=$G6),IF($K6="Sí",2,1),IF(AND($D6=0,X$5=$G6),3,"")) | Y6: =IF(AND(Y$5>$F6,Y$5<=$G6),IF($K6="Sí",2,1),IF(AND($D6=0,Y$5=$G6),3,"")) | ... BO6: =IF(AND(BO$5>$F6,BO$5<=$G6),IF($K6="Sí",2,1),IF(AND($D6=0,BO$5=$G6),3,"")) | BQ6: 44 | BR6: 0 | BS6: 0 | BT6: 0 | BU6: 36 | BV6: 0 | BW6: =L6-80 -> 0 | BX6: =IF($D6=0,0,BQ6/$D6) -> 44 | BY6: =IF($D6=0,0,BR6/$D6) -> 0 | BZ6: =IF($D6=0,0,BS6/$D6) -> 0 | CA6: =IF($D6=0,0,BT6/$D6) -> 0 | CB6: =IF($D6=0,0,BU6/$D6) -> 36 | CC6: =IF($D6=0,0,BV6/$D6) -> 0
A7: 1.2 | B7: Plan de proyecto PM4R (alcance, cronograma, costos, riesgos) | C7: R1 Duvan | D7: 2 | E7: 1.1 | F7: =MAX(G6)+Q7 -> 1 | G7: =F7+D7 -> 3 | H7: =I7-D7 -> 2 | I7: =MIN(H8) -> 4 | J7: =H7-F7 -> 1 | K7: =IF(J7=0,"Sí","") | L7: =SUM(BQ7:BV7) -> 160 | M7: =SUMIFS(Cotizaciones!$J$5:$J$70,Cotizaciones!$C$5:$C$70,A7) -> 0 | N7: =(L7*Supuestos!$B$47+M7*(1+Supuestos!$B$50))*(1+Supuestos!$B$51)/(1-Supuestos!$B$52) -> 25991903 | O7: =$C$3+F7*7 -> 46405 | P7: =$C$3+G7*7-IF(D7>0,1,0) -> 46418 | Q7: 0 | R7: =IF(AND(R$5>$F7,R$5<=$G7),IF($K7="Sí",2,1),IF(AND($D7=0,R$5=$G7),3,"")) | S7: =IF(AND(S$5>$F7,S$5<=$G7),IF($K7="Sí",2,1),IF(AND($D7=0,S$5=$G7),3,"")) -> 1 | T7: =IF(AND(T$5>$F7,T$5<=$G7),IF($K7="Sí",2,1),IF(AND($D7=0,T$5=$G7),3,"")) -> 1 | U7: =IF(AND(U$5>$F7,U$5<=$G7),IF($K7="Sí",2,1),IF(AND($D7=0,U$5=$G7),3,"")) | V7: =IF(AND(V$5>$F7,V$5<=$G7),IF($K7="Sí",2,1),IF(AND($D7=0,V$5=$G7),3,"")) | W7: =IF(AND(W$5>$F7,W$5<=$G7),IF($K7="Sí",2,1),IF(AND($D7=0,W$5=$G7),3,"")) | X7: =IF(AND(X$5>$F7,X$5<=$G7),IF($K7="Sí",2,1),IF(AND($D7=0,X$5=$G7),3,"")) | Y7: =IF(AND(Y$5>$F7,Y$5<=$G7),IF($K7="Sí",2,1),IF(AND($D7=0,Y$5=$G7),3,"")) | ... BO7: =IF(AND(BO$5>$F7,BO$5<=$G7),IF($K7="Sí",2,1),IF(AND($D7=0,BO$5=$G7),3,"")) | BQ7: 87 | BR7: 73 | BS7: 0 | BT7: 0 | BU7: 0 | BV7: 0 | BW7: =L7-160 -> 0 | BX7: =IF($D7=0,0,BQ7/$D7) -> 43.5 | BY7: =IF($D7=0,0,BR7/$D7) -> 36.5 | BZ7: =IF($D7=0,0,BS7/$D7) -> 0 | CA7: =IF($D7=0,0,BT7/$D7) -> 0 | CB7: =IF($D7=0,0,BU7/$D7) -> 0 | CC7: =IF($D7=0,0,BV7/$D7) -> 0
A8: 1.3 | B8: Seguimiento, control de cambios e informes (nivel de esfuerzo) | C8: R1 Duvan | D8: 44 | E8: 1.2 | F8: =MAX(G7)+Q8 -> 3 | G8: =F8+D8 -> 47 | H8: =I8-D8 -> 4 | I8: =MAX($G$6:$G$43) -> 48 | J8: =H8-F8 -> 1 | K8: =IF(J8=0,"Sí","") | L8: =SUM(BQ8:BV8) -> 1100 | M8: =SUMIFS(Cotizaciones!$J$5:$J$70,Cotizaciones!$C$5:$C$70,A8) -> 0 | N8: =(L8*Supuestos!$B$47+M8*(1+Supuestos!$B$50))*(1+Supuestos!$B$51)/(1-Supuestos!$B$52) -> 1.7869433e+08 | O8: =$C$3+F8*7 -> 46419 | P8: =$C$3+G8*7-IF(D8>0,1,0) -> 46726 | Q8: 0 | R8: =IF(AND(R$5>$F8,R$5<=$G8),IF($K8="Sí",2,1),IF(AND($D8=0,R$5=$G8),3,"")) | S8: =IF(AND(S$5>$F8,S$5<=$G8),IF($K8="Sí",2,1),IF(AND($D8=0,S$5=$G8),3,"")) | T8: =IF(AND(T$5>$F8,T$5<=$G8),IF($K8="Sí",2,1),IF(AND($D8=0,T$5=$G8),3,"")) | U8: =IF(AND(U$5>$F8,U$5<=$G8),IF($K8="Sí",2,1),IF(AND($D8=0,U$5=$G8),3,"")) -> 1 | V8: =IF(AND(V$5>$F8,V$5<=$G8),IF($K8="Sí",2,1),IF(AND($D8=0,V$5=$G8),3,"")) -> 1 | W8: =IF(AND(W$5>$F8,W$5<=$G8),IF($K8="Sí",2,1),IF(AND($D8=0,W$5=$G8),3,"")) -> 1 | X8: =IF(AND(X$5>$F8,X$5<=$G8),IF($K8="Sí",2,1),IF(AND($D8=0,X$5=$G8),3,"")) -> 1 | Y8: =IF(AND(Y$5>$F8,Y$5<=$G8),IF($K8="Sí",2,1),IF(AND($D8=0,Y$5=$G8),3,"")) -> 1 | ... BO8: =IF(AND(BO$5>$F8,BO$5<=$G8),IF($K8="Sí",2,1),IF(AND($D8=0,BO$5=$G8),3,"")) | BQ8: 1100 | BR8: 0 | BS8: 0 | BT8: 0 | BU8: 0 | BV8: 0 | BW8: =L8-1100 -> 0 | BX8: =IF($D8=0,0,BQ8/$D8) -> 25 | BY8: =IF($D8=0,0,BR8/$D8) -> 0 | BZ8: =IF($D8=0,0,BS8/$D8) -> 0 | CA8: =IF($D8=0,0,BT8/$D8) -> 0 | CB8: =IF($D8=0,0,BU8/$D8) -> 0 | CC8: =IF($D8=0,0,BV8/$D8) -> 0
A9: 2.1 | B9: Levantamiento en planta y diagnóstico de la situación actual | C9: R3 David Felipe | D9: 3 | E9: 1.1 | F9: =MAX(G6)+Q9 -> 1 | G9: =F9+D9 -> 4 | H9: =I9-D9 -> 1 | I9: =MIN(H10,H11) -> 4 | J9: =H9-F9 -> 0 | K9: =IF(J9=0,"Sí","") -> Sí | L9: =SUM(BQ9:BV9) -> 480 | M9: =SUMIFS(Cotizaciones!$J$5:$J$70,Cotizaciones!$C$5:$C$70,A9) -> 0 | N9: =(L9*Supuestos!$B$47+M9*(1+Supuestos!$B$50))*(1+Supuestos!$B$51)/(1-Supuestos!$B$52) -> 77975709 | O9: =$C$3+F9*7 -> 46405 | P9: =$C$3+G9*7-IF(D9>0,1,0) -> 46425 | Q9: 0 | R9: =IF(AND(R$5>$F9,R$5<=$G9),IF($K9="Sí",2,1),IF(AND($D9=0,R$5=$G9),3,"")) | S9: =IF(AND(S$5>$F9,S$5<=$G9),IF($K9="Sí",2,1),IF(AND($D9=0,S$5=$G9),3,"")) -> 2 | T9: =IF(AND(T$5>$F9,T$5<=$G9),IF($K9="Sí",2,1),IF(AND($D9=0,T$5=$G9),3,"")) -> 2 | U9: =IF(AND(U$5>$F9,U$5<=$G9),IF($K9="Sí",2,1),IF(AND($D9=0,U$5=$G9),3,"")) -> 2 | V9: =IF(AND(V$5>$F9,V$5<=$G9),IF($K9="Sí",2,1),IF(AND($D9=0,V$5=$G9),3,"")) | W9: =IF(AND(W$5>$F9,W$5<=$G9),IF($K9="Sí",2,1),IF(AND($D9=0,W$5=$G9),3,"")) | X9: =IF(AND(X$5>$F9,X$5<=$G9),IF($K9="Sí",2,1),IF(AND($D9=0,X$5=$G9),3,"")) | Y9: =IF(AND(Y$5>$F9,Y$5<=$G9),IF($K9="Sí",2,1),IF(AND($D9=0,Y$5=$G9),3,"")) | ... BO9: =IF(AND(BO$5>$F9,BO$5<=$G9),IF($K9="Sí",2,1),IF(AND($D9=0,BO$5=$G9),3,"")) | BQ9: 0 | BR9: 21 | BS9: 131 | BT9: 131 | BU9: 66 | BV9: 131 | BW9: =L9-480 -> 0 | BX9: =IF($D9=0,0,BQ9/$D9) -> 0 | BY9: =IF($D9=0,0,BR9/$D9) -> 7 | BZ9: =IF($D9=0,0,BS9/$D9) -> 43.666667 | CA9: =IF($D9=0,0,BT9/$D9) -> 43.666667 | CB9: =IF($D9=0,0,BU9/$D9) -> 22 | CC9: =IF($D9=0,0,BV9/$D9) -> 43.666667
A10: 2.2 | B10: VSM actual y línea base de KPIs | C10: R4 Juan | D10: 3 | E10: 2.1 | F10: =MAX(G9)+Q10 -> 4 | G10: =F10+D10 -> 7 | H10: =I10-D10 -> 4 | I10: =MIN(H12) -> 7 | J10: =H10-F10 -> 0 | K10: =IF(J10=0,"Sí","") -> Sí | L10: =SUM(BQ10:BV10) -> 300 | M10: =SUMIFS(Cotizaciones!$J$5:$J$70,Cotizaciones!$C$5:$C$70,A10) -> 0 | N10: =(L10*Supuestos!$B$47+M10*(1+Supuestos!$B$50))*(1+Supuestos!$B$51)/(1-Supuestos!$B$52) -> 48734818 | O10: =$C$3+F10*7 -> 46426 | P10: =$C$3+G10*7-IF(D10>0,1,0) -> 46446 | Q10: 0 | R10: =IF(AND(R$5>$F10,R$5<=$G10),IF($K10="Sí",2,1),IF(AND($D10=0,R$5=$G10),3,"")) | S10: =IF(AND(S$5>$F10,S$5<=$G10),IF($K10="Sí",2,1),IF(AND($D10=0,S$5=$G10),3,"")) | T10: =IF(AND(T$5>$F10,T$5<=$G10),IF($K10="Sí",2,1),IF(AND($D10=0,T$5=$G10),3,"")) | U10: =IF(AND(U$5>$F10,U$5<=$G10),IF($K10="Sí",2,1),IF(AND($D10=0,U$5=$G10),3,"")) | V10: =IF(AND(V$5>$F10,V$5<=$G10),IF($K10="Sí",2,1),IF(AND($D10=0,V$5=$G10),3,"")) -> 2 | W10: =IF(AND(W$5>$F10,W$5<=$G10),IF($K10="Sí",2,1),IF(AND($D10=0,W$5=$G10),3,"")) -> 2 | X10: =IF(AND(X$5>$F10,X$5<=$G10),IF($K10="Sí",2,1),IF(AND($D10=0,X$5=$G10),3,"")) -> 2 | Y10: =IF(AND(Y$5>$F10,Y$5<=$G10),IF($K10="Sí",2,1),IF(AND($D10=0,Y$5=$G10),3,"")) | ... BO10: =IF(AND(BO$5>$F10,BO$5<=$G10),IF($K10="Sí",2,1),IF(AND($D10=0,BO$5=$G10),3,"")) | BQ10: 0 | BR10: 0 | BS10: 38 | BT10: 131 | BU10: 0 | BV10: 131 | BW10: =L10-300 -> 0 | BX10: =IF($D10=0,0,BQ10/$D10) -> 0 | BY10: =IF($D10=0,0,BR10/$D10) -> 0 | BZ10: =IF($D10=0,0,BS10/$D10) -> 12.666667 | CA10: =IF($D10=0,0,BT10/$D10) -> 43.666667 | CB10: =IF($D10=0,0,BU10/$D10) -> 0 | CC10: =IF($D10=0,0,BV10/$D10) -> 43.666667
A11: 2.3 | B11: Arquitectura ISA-95 / ISA-88 y requerimientos | C11: R2 Paula | D11: 3 | E11: 2.1 | F11: =MAX(G9)+Q11 -> 4 | G11: =F11+D11 -> 7 | H11: =I11-D11 -> 4 | I11: =MIN(H12) -> 7 | J11: =H11-F11 -> 0 | K11: =IF(J11=0,"Sí","") -> Sí | L11: =SUM(BQ11:BV11) -> 360 | M11: =SUMIFS(Cotizaciones!$J$5:$J$70,Cotizaciones!$C$5:$C$70,A11) -> 0 | N11: =(L11*Supuestos!$B$47+M11*(1+Supuestos!$B$50))*(1+Supuestos!$B$51)/(1-Supuestos!$B$52) -> 58481781 | O11: =$C$3+F11*7 -> 46426 | P11: =$C$3+G11*7-IF(D11>0,1,0) -> 46446 | Q11: 0 | R11: =IF(AND(R$5>$F11,R$5<=$G11),IF($K11="Sí",2,1),IF(AND($D11=0,R$5=$G11),3,"")) | S11: =IF(AND(S$5>$F11,S$5<=$G11),IF($K11="Sí",2,1),IF(AND($D11=0,S$5=$G11),3,"")) | T11: =IF(AND(T$5>$F11,T$5<=$G11),IF($K11="Sí",2,1),IF(AND($D11=0,T$5=$G11),3,"")) | U11: =IF(AND(U$5>$F11,U$5<=$G11),IF($K11="Sí",2,1),IF(AND($D11=0,U$5=$G11),3,"")) | V11: =IF(AND(V$5>$F11,V$5<=$G11),IF($K11="Sí",2,1),IF(AND($D11=0,V$5=$G11),3,"")) -> 2 | W11: =IF(AND(W$5>$F11,W$5<=$G11),IF($K11="Sí",2,1),IF(AND($D11=0,W$5=$G11),3,"")) -> 2 | X11: =IF(AND(X$5>$F11,X$5<=$G11),IF($K11="Sí",2,1),IF(AND($D11=0,X$5=$G11),3,"")) -> 2 | Y11: =IF(AND(Y$5>$F11,Y$5<=$G11),IF($K11="Sí",2,1),IF(AND($D11=0,Y$5=$G11),3,"")) | ... BO11: =IF(AND(BO$5>$F11,BO$5<=$G11),IF($K11="Sí",2,1),IF(AND($D11=0,BO$5=$G11),3,"")) | BQ11: 0 | BR11: 131 | BS11: 98 | BT11: 0 | BU11: 131 | BV11: 0 | BW11: =L11-360 -> 0 | BX11: =IF($D11=0,0,BQ11/$D11) -> 0 | BY11: =IF($D11=0,0,BR11/$D11) -> 43.666667 | BZ11: =IF($D11=0,0,BS11/$D11) -> 32.666667 | CA11: =IF($D11=0,0,BT11/$D11) -> 0 | CB11: =IF($D11=0,0,BU11/$D11) -> 43.666667 | CC11: =IF($D11=0,0,BV11/$D11) -> 0
