Workbook

Sheet Leeme
A1: Kuajo Automation · Resumen de estimaciones preliminares (línea 1 de yogures, Lácteos Pomar)
A3: Para qué sirve: resume, en pocas cifras, las metas de proceso y los resultados financieros que se presentan en la sustentación intermedia.
A4: Todas las metas futuras y las cifras financieras son ESTIMACIONES PRELIMINARES: se calcularon con los supuestos del caso académico y con precios que en su mayoría son estimaciones. Se confirmarán midiendo la línea base en la visita y en las 2 primeras semanas del proyecto, y con cotizaciones reales.
A5: El detalle completo (5.000 fórmulas, 23 hojas) está en el libro Planeacion_PM4R_Kuajo_Pomar.xlsx. La columna «Detalle» de cada hoja indica la hoja y la celda de ese libro donde se calcula cada cifra. El informe Informe_Kuajo_APM_2026-2_Linea1_Yogures explica cada cálculo en la sección indicada.
A6: Este resumen no reemplaza ni modifica el libro completo ni el informe: ambos se conservan para la entrega final.
A7: Cómo leerlo: Supuestos (datos de entrada) → Proceso (metas de la línea) → Finanzas (inversión y retorno) → Referencias (dónde está cada tema).
A8: Convención de colores: azul = dato de entrada tomado del libro completo (se puede cambiar) · negro = fórmula de este libro · fondo amarillo = supuesto clave que más mueve el resultado.
A9: Redondeo para presentar: en la sustentación se usan cifras redondeadas con «≈» (por ejemplo, VPN ≈ $15.000 M) porque son estimaciones.

Sheet Supuestos
A1: Supuestos clave (datos de entrada)
A2: Valores del caso académico. Los de la propuesta son la meta estimada de cada parámetro y su razón está en la columna E.
A4: Parámetro de la llenadora de vasos U-232 (el cuello de botella) | B4: Hoy | C4: Con la propuesta (estimado) | D4: Unidad | E4: Por qué cambia | F4: Detalle en el libro completo
A5: Tiempo disponible por día | B5: 840 | C5: 840 | D5: min | E5: 2 turnos × (480 − 60 min de pausas); no cambia | F5: VSM_Actual, sección 3 · Supuestos
A6: Cambios de formato o receta por día | B6: 2 | C6: 2 | D6: cambios | E6: Mismo mix de recetas | F6: VSM_Actual!B39:C39
A7: Duración de cada cambio | B7: 90 | C7: 35 | D7: min | E7: Recetas ISA-88 en el PLC y CIP automático (SMED) | F7: VSM_Actual!B40:C40
A8: Fallas por día | B8: 2.2 | C8: 1.5 | D8: fallas | E8: Mantenimiento preventivo y predictivo | F8: VSM_Actual!B41:C41
A9: Tiempo medio de reparación (MTTR) | B9: 25 | C9: 20 | D9: min | E9: Repuestos críticos en sitio y diagnóstico en el SCADA | F9: VSM_Actual!B42:C42
A10: Esperas y microparadas por día | B10: 30 | C10: 15 | D10: min | E10: El MES secuencia el producto hacia la llenadora | F10: VSM_Actual!B43:C43
A11: Rendimiento (velocidad real / nominal) | B11: 0.835 | C11: 0.913 | D11: fracción | E11: Control de peso en lazo cerrado con la pesadora dinámica | F11: VSM_Actual!B47:C47
A12: Calidad (unidades buenas / llenadas) | B12: 0.97 | C12: 0.99 | D12: fracción | E12: Inspección automática y fermentación controlada por pH | F12: VSM_Actual!B48:C48
A13: Llenado a velocidad nominal de las unidades buenas | B13: 7.75 | C13: 9.7222 | D13: h/día | E13: Más producción (de 43.700 a 52.400 kg/día) | F13: VSM_Actual!B38:C38
A15: Producción | B15: Valor | D15: Unidad | E15: Base | F15: Detalle en el libro completo
A16: Producción actual de la línea | B16: 43700 | D16: kg/día | E16: Supuesto del caso, calibrado con los problemas del curso (OEE de 55 %) | F16: Supuestos!B62 · VSM_Actual!B127
A17: Demanda del nuevo contrato | B17: 52400 | D17: kg/día | E17: +20 % que exige el contrato con las cadenas | F17: Supuestos!B66 · VSM_Actual!C127
A19: Supuestos financieros | B19: Valor | D19: Unidad | E19: Base | F19: Detalle en el libro completo
A20: WACC de Pomar | B20: 0.10231 | D20: fracción | E20: CAPM con datos de Damodaran (alimentos procesados), riesgo país y paridad de inflación | F20: Supuestos!B29
A21: Prima por primera implementación | B21: 0.035 | D21: fracción | E21: Riesgo tecnológico de un primer proyecto TDI | F21: Supuestos!B30
A22: Tasa de oportunidad (TIO) de Pomar | B22: =B20+B21 -> 0.13731 | D22: fracción | E22: WACC + prima (fórmula) | F22: Supuestos!B31
A23: Fracción del volumen adicional atribuida a la automatización | B23: 0.5 | D23: fracción | E23: Criterio conservador: la otra mitad se atribuye a la gestión comercial | F23: Supuestos!B67
A24: Captura de beneficios en el año 1 | B24: 0.6 | D24: fracción | E24: Curva de aprendizaje del arranque | F24: Supuestos!B68
A25: Inflación esperada Colombia | B25: 0.04 | D25: fracción | E25: Expectativa del Banco de la República | F25: Supuestos!B7
A26: TRM de la oferta | B26: 3273.49 | D26: COP/US$ | E26: Tasa de cambio de referencia; la oferta tiene cláusula de ajuste si varía más de 5 % | F26: Supuestos!B6
A27: Horizonte de evaluación | B27: 7 | D27: años | E27: Vida útil esperada de la solución | F27: Flujo_Pomar

Sheet Proceso
A1: Metas de proceso estimadas (cálculo preliminar)
A2: Las filas 5 a 10 se calculan aquí con los supuestos; las demás se toman del libro completo (azul). Los valores de hoy son supuestos del caso que se confirman en la visita.
A4: Indicador | B4: Hoy | C4: Meta estimada | D4: Cambio | E4: Cómo se calcula / por qué | F4: Detalle en el libro completo
A5: Disponibilidad de la llenadora | B5: =(Supuestos!B5-Supuestos!B6*Supuestos!B7-(Supuestos!B8*Supuestos!B9+Supuestos!B10))/Supuestos!B5 -> 0.68452381 | C5: =(Supuestos!C5-Supuestos!C6*Supuestos!C7-(Supuestos!C8*Supuestos!C9+Supuestos!C10))/Supuestos!C5 -> 0.86309524 | D5: =IF(B5=0,"",C5/B5-1) -> 0.26086957 | E5: (Disponible − cambios − fallas × MTTR − esperas) / disponible | F5: VSM_Actual!B45:C45
A6: OEE de la llenadora de vasos | B6: =B5*Supuestos!B11*Supuestos!B12 -> 0.55443006 | C6: =C5*Supuestos!C11*Supuestos!C12 -> 0.78012589 | D6: =IF(B6=0,"",C6/B6-1) -> 0.40707719 | E6: Disponibilidad × rendimiento × calidad | F6: VSM_Actual!B49:C49 · Informe, Tabla 6.5
A7: Horas que necesita la llenadora por día | B7: =Supuestos!B13/B6 -> 13.978319 | C7: =Supuestos!C13/C6 -> 12.462348 | D7: =IF(B7=0,"",C7/B7-1) -> -0.1084516 | E7: Llenado a velocidad nominal / OEE | F7: VSM_Actual!B50:C50
A8: Ocupación de la llenadora | B8: =B7/(Supuestos!B5/60) -> 0.99845133 | C8: =C7/(Supuestos!C5/60) -> 0.89016768 | D8: =IF(B8=0,"",C8/B8-1) -> -0.1084516 | E8: Horas necesarias / 14 h disponibles; hoy satura (cuello de botella) | F8: VSM_Actual!B51:C51
A9: OEE mínimo para cumplir la demanda | C9: =Supuestos!C13/(Supuestos!C5/60) -> 0.69444286 | E9: Con un OEE de ≈ 70 % ya se cumple la demanda; la meta de ≈ 78 % deja margen | F9: Derivado de la Tabla 6.5 del informe
A10: Producción (kg/día) | B10: =Supuestos!B16 -> 43700 | C10: =Supuestos!B17 -> 52400 | D10: =IF(B10=0,"",C10/B10-1) -> 0.19908467 | E10: La meta es la demanda del contrato | F10: VSM_Actual!B127:C127
A11: Cumplimiento de la demanda | B11: =B10/Supuestos!B17 -> 0.83396947 | C11: =C10/Supuestos!B17 -> 1 | D11: =IF(B11=0,"",C11/B11-1) -> 0.19908467 | E11: Producción / demanda | F11: VSM_Actual!B131:C131
A12: Throughput (kg/h) | B12: =B10/(Supuestos!B5/60) -> 3121.4286 | C12: =C10/(Supuestos!C5/60) -> 3742.8571 | D12: =IF(B12=0,"",C12/B12-1) -> 0.19908467 | E12: Producción / 14 h disponibles | F12: VSM_Actual!B129:C129
A13: Tiempo de manufactura (MLT) de un lote de Y1 (días) | B13: 4.17 | C13: 3.02 | D13: =IF(B13=0,"",C13/B13-1) -> -0.27577938 | E13: Menos espera en el pulmón (FIFO del MES) y pH en línea | F13: VSM_Actual!B138:C138 · Informe 6.4
A14: Tiempo de cambio de receta (min) | B14: =Supuestos!B7 -> 90 | C14: =Supuestos!C7 -> 35 | D14: =IF(B14=0,"",C14/B14-1) -> -0.61111111 | E14: Recetas ISA-88 y CIP automático | F14: VSM_Actual!B141:C141
A15: Rechazo en inspección | B15: =1-Supuestos!B12 -> 0.03 | C15: =1-Supuestos!C12 -> 0.01 | D15: =IF(B15=0,"",C15/B15-1) -> -0.66666667 | E15: Inspección automática: pesadora, metales y visión | F15: VSM_Actual!B142:C142
A16: MTBF de la llenadora (h) | B16: 4.36 | C16: 8.06 | D16: =IF(B16=0,"",C16/B16-1) -> 0.84862385 | E16: Mantenimiento preventivo y predictivo | F16: VSM_Actual!B139:C139
A17: Utilización de los fermentadores | B17: 0.76 | C17: 0.888 | D17: =IF(B17=0,"",C17/B17-1) -> 0.16842105 | E17: Pasan a ser la restricción con la propuesta | F17: VSM_Actual!B137:C137
A18: Tiempo para rastrear un lote (h) | B18: 6 | C18: 0.5 | D18: =IF(B18=0,"",C18/B18-1) -> -0.91666667 | E18: Genealogía en el MES del silo al pallet | F18: VSM_Actual!B146:C146
A19: Producto vendible simulado (kg/día) | B19: 41186 | C19: 50874 | D19: =IF(B19=0,"",C19/B19-1) -> 0.23522556 | E19: Simulación preliminar: 10 réplicas de 13 semanas (sim.py) | F19: Simulacion!B19 y D19 · Informe 6.9
A21: Control contra el libro completo (OEE meta: debe dar ≈ 0) | C21: =C6-0.780125892857143 -> 0
A22: Valor del libro completo para el control: VSM_Actual!C49 = 0,7801

Sheet Finanzas
A1: Resumen financiero estimado (cálculo preliminar, millones de COP sin IVA)
A2: Los flujos anuales vienen del libro completo (hoja Flujo_Pomar, fila 26); aquí se recalculan VPN, TIR y recuperación con fórmulas para poder revisarlos.
A4: Concepto | B4: Valor ($M) | D4: Base | E4: Detalle en el libro completo
A5: Precio de la Fase 1 (sin IVA) | B5: 8525.92 | D5: Suministros con 10 % de margen + ingeniería (10.160 h) + contingencia + póliza; 73 % de los suministros aún son estimaciones | E5: Precio_Kuajo!C19 · Portada!B5
A6: Inversión total de Pomar en el año 0 | B6: 9604.86 | D6: Precio + costo de la parada de 2 semanas + costo interno de Pomar | E6: Flujo_Pomar!B39
A7: Beneficios anuales en régimen (pesos de 2027) | B7: 8481.49 | D7: Margen del volumen adicional (al 50 %) + menos rechazo + mano de obra + energía + retiros acotados | E7: Beneficios_OPEX!B35
A8: OPEX anual (licencias, soporte, mantenimiento) | B8: 588.24 | D8: Costos de operación que agrega la solución | E8: Beneficios_OPEX!B46
A10: Flujo de caja libre de Pomar ($M)
A11: Año | B11: 0 | C11: 1 | D11: 2 | E11: 3 | F11: 4 | G11: 5 | H11: 6 | I11: 7
A12: Flujo libre (después de impuestos) | B12: -9227.23 | C12: 2541.12 | D12: 5273.37 | E12: 6056.65 | F12: 6285.15 | G12: 6522.8 | H12: 6678.72 | I12: 8718.46
A13: Flujo acumulado | B13: =B12 -> -9227.23 | C13: =B13+C12 -> -6686.11 | D13: =C13+D12 -> -1412.74 | E13: =D13+E12 -> 4643.91 | F13: =E13+F12 -> 10929.06 | G13: =F13+G12 -> 17451.86 | H13: =G13+H12 -> 24130.58 | I13: =H13+I12 -> 32849.04
A14: Flujo descontado a la TIO | B14: =B12/(1+Supuestos!$B$22)^0 -> -9227.23 | C14: =C12/(1+Supuestos!$B$22)^1 -> 2234.3249 | D14: =D12/(1+Supuestos!$B$22)^2 -> 4076.9044 | E14: =E12/(1+Supuestos!$B$22)^3 -> 4117.1426 | F14: =F12/(1+Supuestos!$B$22)^4 -> 3756.6455 | G14: =G12/(1+Supuestos!$B$22)^5 -> 3427.9918 | H14: =H12/(1+Supuestos!$B$22)^6 -> 3086.1717 | I14: =I12/(1+Supuestos!$B$22)^7 -> 3542.3199
A15: Descontado acumulado | B15: =B14 -> -9227.23 | C15: =B15+C14 -> -6992.9051 | D15: =C15+D14 -> -2916.0007 | E15: =D15+E14 -> 1201.1418 | F15: =E15+F14 -> 4957.7873 | G15: =F15+G14 -> 8385.7791 | H15: =G15+H14 -> 11471.951 | I15: =H15+I14 -> 15014.271
A16: Año de recuperación simple (ayuda) | C16: =IF(AND(B13<0,C13>=0),0+(-B13)/C12,0) -> 0 | D16: =IF(AND(C13<0,D13>=0),1+(-C13)/D12,0) -> 0 | E16: =IF(AND(D13<0,E13>=0),2+(-D13)/E12,0) -> 2.2332544 | F16: =IF(AND(E13<0,F13>=0),3+(-E13)/F12,0) -> 0 | G16: =IF(AND(F13<0,G13>=0),4+(-F13)/G12,0) -> 0 | H16: =IF(AND(G13<0,H13>=0),5+(-G13)/H12,0) -> 0 | I16: =IF(AND(H13<0,I13>=0),6+(-H13)/I12,0) -> 0
A17: Año de recuperación descontada (ayuda) | C17: =IF(AND(B15<0,C15>=0),0+(-B15)/C14,0) -> 0 | D17: =IF(AND(C15<0,D15>=0),1+(-C15)/D14,0) -> 0 | E17: =IF(AND(D15<0,E15>=0),2+(-D15)/E14,0) -> 2.7082584 | F17: =IF(AND(E15<0,F15>=0),3+(-E15)/F14,0) -> 0 | G17: =IF(AND(F15<0,G15>=0),4+(-F15)/G14,0) -> 0 | H17: =IF(AND(G15<0,H15>=0),5+(-G15)/H14,0) -> 0 | I17: =IF(AND(H15<0,I15>=0),6+(-H15)/I14,0) -> 0
A18: Fuente de la fila 12: Flujo_Pomar!B26:I26 del libro completo
A20: Indicador | B20: Calculado aquí | C20: Libro completo | D20: Diferencia | E20: Cómo leerlo
A21: VPN a la TIO ($M) | B21: =B12+NPV(Supuestos!B22,C12:I12) -> 15014.271 | C21: 15013.92 | D21: =B21-C21 -> 0.35072606 | E21: Mayor que 0: el proyecto crea valor para Pomar
A22: TIR | B22: =IRR(B12:I12) -> 0.48963312 | C22: 0.48963 | D22: =B22-C22 -> 3.1165149e-06 | E22: Mayor que la TIO (≈ 13,7 %): conviene
A23: Recuperación simple (años) | B23: =SUM(C16:I16) -> 2.2332544 | C23: 2.2333 | D23: =B23-C23 -> -4.5643219e-05 | E23: Años hasta recuperar la inversión
A24: Recuperación descontada (años) | B24: =SUM(C17:I17) -> 2.7082584 | C24: 2.7083 | D24: =B24-C24 -> -4.1614211e-05 | E24: Igual, con el valor del dinero en el tiempo
A25: Relación beneficio/costo | B25: =NPV(Supuestos!B22,C12:I12)/-B12 -> 2.6271699 | C25: 2.6271 | D25: =B25-C25 -> 6.9879374e-05 | E25: Valor presente de los flujos / inversión neta
A26: Libro completo: Flujo_Pomar!B33, B35, B36, B37 y B38
A28: Sensibilidad resumida
A29: Escenario | B29: VPN ($M) | C29: TIR | D29: ¿Conviene? | E29: Detalle en el libro completo
A30: Caso base | B30: 15013.92 | C30: 0.4896 | D30: =IF(B30>0,"Sí","No") -> Sí | E30: Sensibilidad!M5:N5
A31: Beneficios −30 % | B31: 7593.58 | C31: 0.3341 | D31: =IF(B31>0,"Sí","No") -> Sí | E31: Sensibilidad!M6:N6
A32: Inversión +20 % | B32: 13590.38 | C32: 0.4189 | D32: =IF(B32>0,"Sí","No") -> Sí | E32: Sensibilidad!M8:N8
A33: Pesimista: beneficios −30 %, inversión +20 %, OPEX +30 % | B33: 5599.58 | C33: 0.2661 | D33: =IF(B33>0,"Sí","No") -> Sí | E33: Sensibilidad!M11:N11
A34: Beneficios −50 % | B34: 2646.68 | C34: 0.2128 | D34: =IF(B34>0,"Sí","No") -> Sí | E34: Sensibilidad!M7:N7
A35: Sin el volumen adicional (solo eficiencia) | B35: -3938.3 | C35: -0.0092 | D35: =IF(B35>0,"Sí","No") -> No | E35: Sensibilidad!M13:N13
A36: Punto de equilibrio: el VPN es 0 con ≈ 39 % de los beneficios estimados (Sensibilidad!M16).
A38: Rentabilidad para Kuajo
A39: Concepto | B39: Valor | D39: Base | E39: Detalle en el libro completo
A40: Utilidad neta del proyecto ($M) | B40: 934.53 | D40: Ingresos − suministros − nómina − gastos − contingencia − impuestos | E40: Kuajo_PyG_Flujo!B56
A41: Margen neto | B41: =B40/B5 -> 0.10961046 | D41: Utilidad / precio | E41: Kuajo_PyG_Flujo!B57
A42: Crédito rotativo máximo ($M) | B42: 1316.12 | D42: Cada hito se cobra a 30 días y las compras se pagan antes (mes 8) | E42: Kuajo_PyG_Flujo!B63
A44: Líneas 2 y 3 (referencia preliminar ±30 %)
A45: Línea | B45: Precio ($M) | C45: VPN ($M) | D45: TIR | E45: Detalle en el libro completo
A46: Línea 3 · UHT (Fase 2, 26 semanas) | B46: 3150 | C46: 6408 | D46: 0.573 | E46: Lineas_2_3 · Informe 8.3
...

Sheet Referencias
A1: Dónde está el detalle de cada tema
A3: Tema | B3: Hoja del libro completo (Planeacion_PM4R_Kuajo_Pomar.xlsx) | C3: Sección del informe | D3: Qué se encuentra
A4: Datos de entrada y fuentes | B4: Supuestos, Fuentes | C4: 4, 13 y Fuentes | D4: Todos los supuestos con su fuente
A5: Situación actual, VSM, OEE, MLT y KPIs | B5: VSM_Actual | C5: 6.1 a 6.8 | D5: Cálculo de la línea base y de las metas
A6: Simulación de eventos discretos | B6: Simulacion (y sim.py) | C6: 6.9 | D6: Escenarios, 10 réplicas, resultados
A7: Recursos compartidos de la planta | B7: Recursos_compartidos | C7: 5 | D7: Acopio, servicios y cámara
A8: Líneas 2 y 3 y planta completa | B8: Lineas_2_3 | C8: 8 y 9, anexo C | D8: Referencia ±30 %
A9: Instrumentos y P&ID | B9: Instrumentos | C9: 12 | D9: 86 tags, 53 sensores
A10: Presupuesto y cotizaciones | B10: Cotizaciones, Precio_Kuajo | C10: 13.5 | D10: Partidas, fuentes y estimaciones
A11: Cronograma, recursos y curva S | B11: Cronograma, Curva_S, EDT, Nomina_Kuajo | C11: 13.1 a 13.4 | D11: CPM, histograma, horas por persona
A12: Beneficios y OPEX | B12: Beneficios_OPEX | C12: 13.6 y 13.7 | D12: Beneficios anuales y costos de operación
A13: Flujo de caja, VPN, TIR y recuperación | B13: Flujo_Pomar | C13: 13.8 y 13.9 | D13: Flujo a 7 años y WACC
A14: Sensibilidad | B14: Sensibilidad | C14: 13.10 | D14: Escenarios y punto de equilibrio
... A17: Oferta comercial | B17: Oferta | C17: 14 | D17: Precio, hitos de pago y condiciones
